Workbook

Sheet Leaf Green Seeds
A1: Seeds for the English Leaf Green version farmed by po and 10Ben. | J1: Instead of pressing the A button on the title screen, press Start instead | P1: Instead of pressing the A button on the title screen, press L instead
A2: # | B2: Intro Time ms (GBA) | C2: Intro Time ms (NDS) | D2: MONO/LR | E2: MONO/L=A | F2: MONO/HELP | G2: STEREO/LR | H2: STEREO/L=A | I2: STEREO/HELP | J2: MONO/LR, Start | K2: MONO/L=A, Start | L2: MONO/HELP, Start | M2: STEREO/LR, Start | N2: STEREO/L=A, Start | O2: STEREO/HELP, Start | P2: MONO/L=A, L | Q2: STEREO/L=A, L
A3: 1 | B3: 33752 | C3: 34748 | D3: A088 | E3: A075 | F3: A080 | G3: A0B3 | H3: A0B7 | I3: A0AB | J3: A07E | K3: A077 | L3: A06D | M3: A0B7 | N3: A0AD | O3: A0AC | P3: A07E | Q3: A0B3
A4: 2 | B4: 33768 | C4: 34764 | D4: ECCF | E4: ECC4 | F4: ECC6 | G4: ECC5 | H4: ECBC | I4: ECBD | J4: ECBD | K4: ECB4 | L4: ECB5 | M4: ECC6 | N4: ECBF | O4: ECB5 | P4: ECBC | Q4: ECC2
A5: 3 | B5: 33784 | C5: 34780 | D5: 36B5 | E5: 36A7 | F5: 36A8 | G5: 36CE | H5: 36CF | I5: 36D0 | J5: 36AD | K5: 36A4 | L5: 36A0 | M5: 36C6 | N5: 36C7 | O5: 36BE | P5: 36A9 | Q5: 36C2
A6: 4 | B6: 33808 | C6: 34804 | D6: 7F43 | E6: 7F42 | F6: 7F44 | G6: 7F43 | H6: 7F42 | I6: 7F44 | J6: 7F44 | K6: 7F3A | L6: 7F3C | M6: 7F44 | N6: 7F3A | O6: 7F33 | P6: 7F37 | Q6: 7F40
A7: 5 | B7: 33824 | C7: 34820 | D7: C938 | E7: C92C | F7: C92F | G7: C95B | H7: C944 | I7: C951 | J7: C930 | K7: C924 | L7: C920 | M7: C94F | N7: C93C | O7: C93D | P7: C929 | Q7: C94B
A8: 6 | B8: 33840 | C8: 34836 | D8: 11B7 | E8: 11B5 | F8: 11AF | G8: 11B7 | H8: 11AC | I8: 11AF | J8: 11BA | K8: 11A4 | L8: 11B2 | M8: 11AE | N8: 11AD | O8: 11A6 | P8: 11A9 | Q8: 11B7
A9: 7 | B9: 33856 | C9: 34852 | D9: 3FCC | E9: 3FC2 | F9: 3FC4 | G9: 3FEA | H9: 3FE1 | I9: 3FE2 | J9: 3FB8 | K9: 3FAF | L9: 3FBB | M9: 3FD7 | N9: 3FD9 | O9: 3FD9 | P9: 3FBF | Q9: 3FDD
A10: 8 | B10: 33872 | C10: 34868 | D10: 96DE | E10: 96D5 | F10: 96DE | G10: 9704 | H10: 96FE | I10: 96FC | J10: 96DE | K10: 96D7 | L10: 96D9 | M10: 96F4 | N10: 96F3 | O10: 96F7 | P10: 96DC | Q10: 96F8
A11: 9 | B11: 33888 | C11: 34884 | D11: D4C9 | E11: D4C0 | F11: D4CA | G11: D4C9 | H11: D4C0 | I11: D4C1 | J11: D4C1 | K11: D4C0 | L11: D4B9 | M11: D4C9 | N11: D4B8 | O11: D4B9 | P11: D4BD | Q11: D4BD
A12: 10 | B12: 33904 | C12: 34900 | D12: 1E96 | E12: 1E8D | F12: 1E98 | G12: 1EB5 | H12: 1EAC | I12: 1EB6 | J12: 1E8E | K12: 1E85 | L12: 1E90 | M12: 1EB6 | N12: 1EA4 | O12: 1EAE | P12: 1E94 | Q12: 1EA9
A13: 11 | B13: 33920 | C13: 34916 | D13: 9243 | E13: 9232 | F13: 923D | G13: 9243 | H13: 923A | I13: 923B | J13: 9233 | K13: 9232 | L13: 922B | M13: 923B | N13: 922A | O13: 922B | P13: 922F | Q13: 922F
A14: 12 | B14: 33936 | C14: 34932 | D14: CF14 | E14: CF04 | F14: CF05 | G14: CF30 | H14: CF1B | I14: CF1C | J14: CF0E | K14: CEFC | L14: CF07 | M14: CF27 | N14: CF1B | O14: CF1C | P14: CF01 | Q14: CF18
... A2433: 2431 | B2433: 74520 | C2433: 75516 | D2433: E678 | E2433: E66F | F2433: E679 | G2433: E6B8 | H2433: E6AE | I2433: E6A5 | J2433: 0E96 | K2433: 7E20 | L2433: BC9B | M2433: 3222 | N2433: 0EAA | O2433: E6A7 | P2433: E66C | Q2433: E6AB
A2434: 2432 | B2434: 74536 | C2434: 75532 | D2434: 3234 | E2434: 3221 | F2434: 322D | G2434: 322A | H2434: 3221 | I2434: 322C | J2434: 5715 | K2434: BC90 | M2434: 7C35 | N2434: 5714 | O2434: 3224 | P2434: 322A | Q2434: 321E
A2435: 2433 | B2435: 74552 | C2435: 75548 | D2435: 7C21 | E2435: 7C0C | F2435: 7C16 | G2435: 7C3F | H2435: 7C34 | I2435: 7C33 | J2435: 7E1F | M2435: C492 | N2435: 7E3D | O2435: 7C2F | P2435: 7C15 | Q2435: 7C2F
A2436: 2434 | B2436: 74568 | C2436: 75564 | D2436: C492 | E2436: C493 | F2436: C48A | G2436: C492 | H2436: C491 | I2436: C494 | J2436: BC99 | M2436: 0EB3 | N2436: BCAF | O2436: C48A | P2436: C486 | Q2436: C48E
A2437: 2435 | B2437: 74584 | C2437: 75580 | D2437: 0EA1 | E2437: 0E8C | F2437: 0E8D | G2437: 0EBB | H2437: 0EB2 | I2437: 0EB3 | M2437: 5720 | O2437: 0EAB | P2437: 0E92 | Q2437: 0EAF
A2438: 2436 | B2438: 74600 | C2438: 75596 | D2438: 5727 | E2438: 5714 | F2438: 5715 | G2438: 5725 | H2438: 5714 | I2438: 5715 | M2438: 7E3E | O2438: 570D | P2438: 5711 | Q2438: 5711
A2439: 2437 | B2439: 74616 | C2439: 75612 | D2439: 7E27 | E2439: 7E29 | F2439: 7E29 | G2439: 7E46 | H2439: 7E45 | I2439: 7E46 | M2439: BCBF | O2439: 7E36 | P2439: 7E1B | Q2439: 7E3A
A2440: 2438 | B2440: 74638 | C2440: 75632 | D2440: BCAA | E2440: BCA2 | F2440: BCA2 | G2440: BCC7 | H2440: BCBE | I2440: BCB8 | O2440: BCBA | P2440: BC95 | Q2440: BCB4

Sheet Held Button
A1: Hold any of the Buttons B, Start, Select, Up, Left, Right, Down before you boot up the game. You can let go of it as soon you can see the leaves on the title screen. | J1: Instead of pressing the A button on the title screen, press Start instead | P1: Instead of pressing the A button on the title screen, press L instead
A2: # | B2: Intro Time ms (GBA) | C2: Intro Time ms (NDS) | D2: MONO/LR | E2: MONO/L=A | F2: MONO/HELP | G2: STEREO/LR | H2: STEREO/L=A | I2: STEREO/HELP | J2: MONO/LR, Start | K2: MONO/L=A, Start | L2: MONO/HELP, Start | M2: STEREO/LR, Start | N2: STEREO/L=A, Start | O2: STEREO/HELP, Start | P2: MONO/L=A, L | Q2: STEREO/L=A, L
A3: 1 | B3: 33752 | C3: 34748 | D3: A087 | E3: A074 | F3: A087 | G3: A0B2 | H3: A0B6 | I3: A0B2 | J3: =IFERROR(DEC2HEX(MOD((HEX2DEC('Leaf Green Seeds'!J3) - 1 ),65536),4),"") -> A07D | K3: =IFERROR(DEC2HEX(MOD((HEX2DEC('Leaf Green Seeds'!K3) - 1 ),65536),4),"") -> A076 | L3: =IFERROR(DEC2HEX(MOD((HEX2DEC('Leaf Green Seeds'!L3) + 7 ),65536),4),"") -> A074 | M3: =IFERROR(DEC2HEX(MOD((HEX2DEC('Leaf Green Seeds'!M3) - 1 ),65536),4),"") -> A0B6 | N3: =IFERROR(DEC2HEX(MOD((HEX2DEC('Leaf Green Seeds'!N3) - 1 ),65536),4),"") -> A0AC | O3: =IFERROR(DEC2HEX(MOD((HEX2DEC('Leaf Green Seeds'!O3) + 7 ),65536),4),"") -> A0B3 | P3: =IFERROR(DEC2HEX(MOD((HEX2DEC('Leaf Green Seeds'!P3) - 1 ),65536),4),"") -> A07D | Q3: =IFERROR(DEC2HEX(MOD((HEX2DEC('Leaf Green Seeds'!Q3) - 1 ),65536),4),"") -> A0B2
A4: 2 | B4: 33768 | C4: 34764 | D4: ECCE | E4: ECC3 | F4: ECCD | G4: ECC4 | H4: ECBB | I4: ECC4 | J4: =IFERROR(DEC2HEX(MOD((HEX2DEC('Leaf Green Seeds'!J4) - 1 ),65536),4),"") -> ECBC | K4: =IFERROR(DEC2HEX(MOD((HEX2DEC('Leaf Green Seeds'!K4) - 1 ),65536),4),"") -> ECB3 | L4: =IFERROR(DEC2HEX(MOD((HEX2DEC('Leaf Green Seeds'!L4) + 7 ),65536),4),"") -> ECBC | M4: =IFERROR(DEC2HEX(MOD((HEX2DEC('Leaf Green Seeds'!M4) - 1 ),65536),4),"") -> ECC5 | N4: =IFERROR(DEC2HEX(MOD((HEX2DEC('Leaf Green Seeds'!N4) - 1 ),65536),4),"") -> ECBE | O4: =IFERROR(DEC2HEX(MOD((HEX2DEC('Leaf Green Seeds'!O4) + 7 ),65536),4),"") -> ECBC | P4: =IFERROR(DEC2HEX(MOD((HEX2DEC('Leaf Green Seeds'!P4) - 1 ),65536),4),"") -> ECBB | Q4: =IFERROR(DEC2HEX(MOD((HEX2DEC('Leaf Green Seeds'!Q4) - 1 ),65536),4),"") -> ECC1
A5: 3 | B5: 33784 | C5: 34780 | D5: 36B4 | E5: 36A6 | F5: 36AF | G5: 36CD | H5: 36CE | I5: 36D7 | J5: =IFERROR(DEC2HEX(MOD((HEX2DEC('Leaf Green Seeds'!J5) - 1 ),65536),4),"") -> 36AC | K5: =IFERROR(DEC2HEX(MOD((HEX2DEC('Leaf Green Seeds'!K5) - 1 ),65536),4),"") -> 36A3 | L5: =IFERROR(DEC2HEX(MOD((HEX2DEC('Leaf Green Seeds'!L5) + 7 ),65536),4),"") -> 36A7 | M5: =IFERROR(DEC2HEX(MOD((HEX2DEC('Leaf Green Seeds'!M5) - 1 ),65536),4),"") -> 36C5 | N5: =IFERROR(DEC2HEX(MOD((HEX2DEC('Leaf Green Seeds'!N5) - 1 ),65536),4),"") -> 36C6 | O5: =IFERROR(DEC2HEX(MOD((HEX2DEC('Leaf Green Seeds'!O5) + 7 ),65536),4),"") -> 36C5 | P5: =IFERROR(DEC2HEX(MOD((HEX2DEC('Leaf Green Seeds'!P5) - 1 ),65536),4),"") -> 36A8 | Q5: =IFERROR(DEC2HEX(MOD((HEX2DEC('Leaf Green Seeds'!Q5) - 1 ),65536),4),"") -> 36C1
A6: 4 | B6: 33808 | C6: 34804 | D6: 7F42 | E6: 7F41 | F6: 7F4B | G6: 7F42 | H6: 7F41 | I6: 7F4B | J6: =IFERROR(DEC2HEX(MOD((HEX2DEC('Leaf Green Seeds'!J6) - 1 ),65536),4),"") -> 7F43 | K6: =IFERROR(DEC2HEX(MOD((HEX2DEC('Leaf Green Seeds'!K6) - 1 ),65536),4),"") -> 7F39 | L6: =IFERROR(DEC2HEX(MOD((HEX2DEC('Leaf Green Seeds'!L6) + 7 ),65536),4),"") -> 7F43 | M6: =IFERROR(DEC2HEX(MOD((HEX2DEC('Leaf Green Seeds'!M6) - 1 ),65536),4),"") -> 7F43 | N6: =IFERROR(DEC2HEX(MOD((HEX2DEC('Leaf Green Seeds'!N6) - 1 ),65536),4),"") -> 7F39 | O6: =IFERROR(DEC2HEX(MOD((HEX2DEC('Leaf Green Seeds'!O6) + 7 ),65536),4),"") -> 7F3A | P6: =IFERROR(DEC2HEX(MOD((HEX2DEC('Leaf Green Seeds'!P6) - 1 ),65536),4),"") -> 7F36 | Q6: =IFERROR(DEC2HEX(MOD((HEX2DEC('Leaf Green Seeds'!Q6) - 1 ),65536),4),"") -> 7F3F
A7: 5 | B7: 33824 | C7: 34820 | D7: C937 | E7: C92B | F7: C936 | G7: C95A | H7: C943 | I7: C958 | J7: =IFERROR(DEC2HEX(MOD((HEX2DEC('Leaf Green Seeds'!J7) - 1 ),65536),4),"") -> C92F | K7: =IFERROR(DEC2HEX(MOD((HEX2DEC('Leaf Green Seeds'!K7) - 1 ),65536),4),"") -> C923 | L7: =IFERROR(DEC2HEX(MOD((HEX2DEC('Leaf Green Seeds'!L7) + 7 ),65536),4),"") -> C927 | M7: =IFERROR(DEC2HEX(MOD((HEX2DEC('Leaf Green Seeds'!M7) - 1 ),65536),4),"") -> C94E | N7: =IFERROR(DEC2HEX(MOD((HEX2DEC('Leaf Green Seeds'!N7) - 1 ),65536),4),"") -> C93B | O7: =IFERROR(DEC2HEX(MOD((HEX2DEC('Leaf Green Seeds'!O7) + 7 ),65536),4),"") -> C944 | P7: =IFERROR(DEC2HEX(MOD((HEX2DEC('Leaf Green Seeds'!P7) - 1 ),65536),4),"") -> C928 | Q7: =IFERROR(DEC2HEX(MOD((HEX2DEC('Leaf Green Seeds'!Q7) - 1 ),65536),4),"") -> C94A
A8: 6 | B8: 33840 | C8: 34836 | D8: 11B6 | E8: 11B4 | F8: 11B6 | G8: 11B6 | H8: 11AB | I8: 11B6 | J8: =IFERROR(DEC2HEX(MOD((HEX2DEC('Leaf Green Seeds'!J8) - 1 ),65536),4),"") -> 11B9 | K8: =IFERROR(DEC2HEX(MOD((HEX2DEC('Leaf Green Seeds'!K8) - 1 ),65536),4),"") -> 11A3 | L8: =IFERROR(DEC2HEX(MOD((HEX2DEC('Leaf Green Seeds'!L8) + 7 ),65536),4),"") -> 11B9 | M8: =IFERROR(DEC2HEX(MOD((HEX2DEC('Leaf Green Seeds'!M8) - 1 ),65536),4),"") -> 11AD | N8: =IFERROR(DEC2HEX(MOD((HEX2DEC('Leaf Green Seeds'!N8) - 1 ),65536),4),"") -> 11AC | O8: =IFERROR(DEC2HEX(MOD((HEX2DEC('Leaf Green Seeds'!O8) + 7 ),65536),4),"") -> 11AD | P8: =IFERROR(DEC2HEX(MOD((HEX2DEC('Leaf Green Seeds'!P8) - 1 ),65536),4),"") -> 11A8 | Q8: =IFERROR(DEC2HEX(MOD((HEX2DEC('Leaf Green Seeds'!Q8) - 1 ),65536),4),"") -> 11B6
A9: 7 | B9: 33856 | C9: 34852 | D9: 3FCB | E9: 3FC1 | F9: 3FCB | G9: 3FE9 | H9: 3FE0 | I9: 3FE9 | J9: =IFERROR(DEC2HEX(MOD((HEX2DEC('Leaf Green Seeds'!J9) - 1 ),65536),4),"") -> 3FB7 | K9: =IFERROR(DEC2HEX(MOD((HEX2DEC('Leaf Green Seeds'!K9) - 1 ),65536),4),"") -> 3FAE | L9: =IFERROR(DEC2HEX(MOD((HEX2DEC('Leaf Green Seeds'!L9) + 7 ),65536),4),"") -> 3FC2 | M9: =IFERROR(DEC2HEX(MOD((HEX2DEC('Leaf Green Seeds'!M9) - 1 ),65536),4),"") -> 3FD6 | N9: =IFERROR(DEC2HEX(MOD((HEX2DEC('Leaf Green Seeds'!N9) - 1 ),65536),4),"") -> 3FD8 | O9: =IFERROR(DEC2HEX(MOD((HEX2DEC('Leaf Green Seeds'!O9) + 7 ),65536),4),"") -> 3FE0 | P9: =IFERROR(DEC2HEX(MOD((HEX2DEC('Leaf Green Seeds'!P9) - 1 ),65536),4),"") -> 3FBE | Q9: =IFERROR(DEC2HEX(MOD((HEX2DEC('Leaf Green Seeds'!Q9) - 1 ),65536),4),"") -> 3FDC
A10: 8 | B10: 33872 | C10: 34868 | D10: 96DD | E10: 96D4 | F10: 96E5 | G10: 9703 | H10: 96FD | I10: 9703 | J10: =IFERROR(DEC2HEX(MOD((HEX2DEC('Leaf Green Seeds'!J10) - 1 ),65536),4),"") -> 96DD | K10: =IFERROR(DEC2HEX(MOD((HEX2DEC('Leaf Green Seeds'!K10) - 1 ),65536),4),"") -> 96D6 | L10: =IFERROR(DEC2HEX(MOD((HEX2DEC('Leaf Green Seeds'!L10) + 7 ),65536),4),"") -> 96E0 | M10: =IFERROR(DEC2HEX(MOD((HEX2DEC('Leaf Green Seeds'!M10) - 1 ),65536),4),"") -> 96F3 | N10: =IFERROR(DEC2HEX(MOD((HEX2DEC('Leaf Green Seeds'!N10) - 1 ),65536),4),"") -> 96F2 | O10: =IFERROR(DEC2HEX(MOD((HEX2DEC('Leaf Green Seeds'!O10) + 7 ),65536),4),"") -> 96FE | P10: =IFERROR(DEC2HEX(MOD((HEX2DEC('Leaf Green Seeds'!P10) - 1 ),65536),4),"") -> 96DB | Q10: =IFERROR(DEC2HEX(MOD((HEX2DEC('Leaf Green Seeds'!Q10) - 1 ),65536),4),"") -> 96F7
A11: 9 | B11: 33888 | C11: 34884 | D11: D4C8 | E11: D4BF | F11: D4D1 | G11: D4C8 | H11: D4BF | I11: D4C8 | J11: =IFERROR(DEC2HEX(MOD((HEX2DEC('Leaf Green Seeds'!J11) - 1 ),65536),4),"") -> D4C0 | K11: =IFERROR(DEC2HEX(MOD((HEX2DEC('Leaf Green Seeds'!K11) - 1 ),65536),4),"") -> D4BF | L11: =IFERROR(DEC2HEX(MOD((HEX2DEC('Leaf Green Seeds'!L11) + 7 ),65536),4),"") -> D4C0 | M11: =IFERROR(DEC2HEX(MOD((HEX2DEC('Leaf Green Seeds'!M11) - 1 ),65536),4),"") -> D4C8 | N11: =IFERROR(DEC2HEX(MOD((HEX2DEC('Leaf Green Seeds'!N11) - 1 ),65536),4),"") -> D4B7 | O11: =IFERROR(DEC2HEX(MOD((HEX2DEC('Leaf Green Seeds'!O11) + 7 ),65536),4),"") -> D4C0 | P11: =IFERROR(DEC2HEX(MOD((HEX2DEC('Leaf Green Seeds'!P11) - 1 ),65536),4),"") -> D4BC | Q11: =IFERROR(DEC2HEX(MOD((HEX2DEC('Leaf Green Seeds'!Q11) - 1 ),65536),4),"") -> D4BC
A12: 10 | B12: 33904 | C12: 34900 | D12: 1E95 | E12: 1E8C | F12: 1E9F | G12: 1EB4 | H12: 1EAB | I12: 1EBD | J12: =IFERROR(DEC2HEX(MOD((HEX2DEC('Leaf Green Seeds'!J12) - 1 ),65536),4),"") -> 1E8D | K12: =IFERROR(DEC2HEX(MOD((HEX2DEC('Leaf Green Seeds'!K12) - 1 ),65536),4),"") -> 1E84 | L12: =IFERROR(DEC2HEX(MOD((HEX2DEC('Leaf Green Seeds'!L12) + 7 ),65536),4),"") -> 1E97 | M12: =IFERROR(DEC2HEX(MOD((HEX2DEC('Leaf Green Seeds'!M12) - 1 ),65536),4),"") -> 1EB5 | N12: =IFERROR(DEC2HEX(MOD((HEX2DEC('Leaf Green Seeds'!N12) - 1 ),65536),4),"") -> 1EA3 | O12: =IFERROR(DEC2HEX(MOD((HEX2DEC('Leaf Green Seeds'!O12) + 7 ),65536),4),"") -> 1EB5 | P12: =IFERROR(DEC2HEX(MOD((HEX2DEC('Leaf Green Seeds'!P12) - 1 ),65536),4),"") -> 1E93 | Q12: =IFERROR(DEC2HEX(MOD((HEX2DEC('Leaf Green Seeds'!Q12) - 1 ),65536),4),"") -> 1EA8
A13: 11 | B13: 33920 | C13: 34916 | D13: 9242 | E13: 9231 | F13: 9244 | G13: 9242 | H13: 9239 | I13: 9242 | J13: =IFERROR(DEC2HEX(MOD((HEX2DEC('Leaf Green Seeds'!J13) - 1 ),65536),4),"") -> 9232 | K13: =IFERROR(DEC2HEX(MOD((HEX2DEC('Leaf Green Seeds'!K13) - 1 ),65536),4),"") -> 9231 | L13: =IFERROR(DEC2HEX(MOD((HEX2DEC('Leaf Green Seeds'!L13) + 7 ),65536),4),"") -> 9232 | M13: =IFERROR(DEC2HEX(MOD((HEX2DEC('Leaf Green Seeds'!M13) - 1 ),65536),4),"") -> 923A | N13: =IFERROR(DEC2HEX(MOD((HEX2DEC('Leaf Green Seeds'!N13) - 1 ),65536),4),"") -> 9229 | O13: =IFERROR(DEC2HEX(MOD((HEX2DEC('Leaf Green Seeds'!O13) + 7 ),65536),4),"") -> 9232 | P13: =IFERROR(DEC2HEX(MOD((HEX2DEC('Leaf Green Seeds'!P13) - 1 ),65536),4),"") -> 922E | Q13: =IFERROR(DEC2HEX(MOD((HEX2DEC('Leaf Green Seeds'!Q13) - 1 ),65536),4),"") -> 922E
A14: 12 | B14: 33936 | C14: 34932 | D14: CF13 | E14: CF03 | F14: CF0C | G14: CF2F | H14: CF1A | I14: CF23 | J14: =IFERROR(DEC2HEX(MOD((HEX2DEC('Leaf Green Seeds'!J14) - 1 ),65536),4),"") -> CF0D | K14: =IFERROR(DEC2HEX(MOD((HEX2DEC('Leaf Green Seeds'!K14) - 1 ),65536),4),"") -> CEFB | L14: =IFERROR(DEC2HEX(MOD((HEX2DEC('Leaf Green Seeds'!L14) + 7 ),65536),4),"") -> CF0E | M14: =IFERROR(DEC2HEX(MOD((HEX2DEC('Leaf Green Seeds'!M14) - 1 ),65536),4),"") -> CF26 | N14: =IFERROR(DEC2HEX(MOD((HEX2DEC('Leaf Green Seeds'!N14) - 1 ),65536),4),"") -> CF1A | O14: =IFERROR(DEC2HEX(MOD((HEX2DEC('Leaf Green Seeds'!O14) + 7 ),65536),4),"") -> CF23 | P14: =IFERROR(DEC2HEX(MOD((HEX2DEC('Leaf Green Seeds'!P14) - 1 ),65536),4),"") -> CF00 | Q14: =IFERROR(DEC2HEX(MOD((HEX2DEC('Leaf Green Seeds'!Q14) - 1 ),65536),4),"") -> CF17
... A2440: 2438 | B2440: 74638 | C2440: 75632 | D2440: BCA9 | E2440: BCA1 | F2440: BCA9 | G2440: BCC6 | H2440: BCBD | I2440: BCBF | J2440: =IFERROR(DEC2HEX(MOD((HEX2DEC('Leaf Green Seeds'!J2440) - 1 ),65536),4),"") | K2440: =IFERROR(DEC2HEX(MOD((HEX2DEC('Leaf Green Seeds'!K2440) - 1 ),65536),4),"") | L2440: =IFERROR(DEC2HEX(MOD((HEX2DEC('Leaf Green Seeds'!L2440) + 7 ),65536),4),"") | M2440: =IFERROR(DEC2HEX(MOD((HEX2DEC('Leaf Green Seeds'!M2440) - 1 ),65536),4),"") | N2440: =IFERROR(DEC2HEX(MOD((HEX2DEC('Leaf Green Seeds'!N2440) - 1 ),65536),4),"") | O2440: =IFERROR(DEC2HEX(MOD((HEX2DEC('Leaf Green Seeds'!O2440) + 7 ),65536),4),"") -> BCC1 | P2440: =IFERROR(DEC2HEX(MOD((HEX2DEC('Leaf Green Seeds'!P2440) - 1 ),65536),4),"") -> BC94 | Q2440: =IFERROR(DEC2HEX(MOD((HEX2DEC('Leaf Green Seeds'!Q2440) - 1 ),65536),4),"") -> BCB3

Sheet Held Button (A)
A1: Hold the A Button before you boot up the game. Let go of it as soon you can see the leaves on the Venusaur title screen. | J1: Instead of pressing the A button on the title screen, press Start instead | P1: Instead of pressing the A button on the title screen, press L instead
A2: # | B2: Intro Time ms (GBA) | C2: Intro Time ms (NDS) | D2: MONO/LR | E2: MONO/L=A | F2: MONO/HELP | G2: STEREO/LR | H2: STEREO/L=A | I2: STEREO/HELP | J2: MONO/LR, Start | K2: MONO/L=A, Start | L2: MONO/HELP, Start | M2: STEREO/LR, Start | N2: STEREO/L=A, Start | O2: STEREO/HELP, Start | P2: MONO/L=A, L | Q2: STEREO/L=A, L
A3: 1 | B3: 33752 | C3: 34748 | D3: =IFERROR(DEC2HEX(MOD((HEX2DEC('Leaf Green Seeds'!D3) - 18 ),65536),4),"") -> A076 | E3: =IFERROR(DEC2HEX(MOD((HEX2DEC('Leaf Green Seeds'!E3) - 8 ),65536),4),"") -> A06D | F3: =IFERROR(DEC2HEX(MOD((HEX2DEC('Leaf Green Seeds'!F3) + 3 ),65536),4),"") -> A083 | G3: =IFERROR(DEC2HEX(MOD((HEX2DEC('Leaf Green Seeds'!G3) - 18 ),65536),4),"") -> A0A1 | H3: =IFERROR(DEC2HEX(MOD((HEX2DEC('Leaf Green Seeds'!H3) - 8 ),65536),4),"") -> A0AF | I3: =IFERROR(DEC2HEX(MOD((HEX2DEC('Leaf Green Seeds'!I3) + 3 ),65536),4),"") -> A0AE | J3: =IFERROR(DEC2HEX(MOD((HEX2DEC('Leaf Green Seeds'!J3) - 18 ),65536),4),"") -> A06C | K3: =IFERROR(DEC2HEX(MOD((HEX2DEC('Leaf Green Seeds'!K3) - 8 ),65536),4),"") -> A06F | L3: =IFERROR(DEC2HEX(MOD((HEX2DEC('Leaf Green Seeds'!L3) + 3 ),65536),4),"") -> A070 | M3: =IFERROR(DEC2HEX(MOD((HEX2DEC('Leaf Green Seeds'!M3) - 18 ),65536),4),"") -> A0A5 | N3: =IFERROR(DEC2HEX(MOD((HEX2DEC('Leaf Green Seeds'!N3) - 8 ),65536),4),"") -> A0A5 | O3: =IFERROR(DEC2HEX(MOD((HEX2DEC('Leaf Green Seeds'!O3) + 3 ),65536),4),"") -> A0AF | P3: =IFERROR(DEC2HEX(MOD((HEX2DEC('Leaf Green Seeds'!P3) - 8 ),65536),4),"") -> A076 | Q3: =IFERROR(DEC2HEX(MOD((HEX2DEC('Leaf Green Seeds'!Q3) - 8 ),65536),4),"") -> A0AB
A4: 2 | B4: 33768 | C4: 34764 | D4: =IFERROR(DEC2HEX(MOD((HEX2DEC('Leaf Green Seeds'!D4) - 18 ),65536),4),"") -> ECBD | E4: =IFERROR(DEC2HEX(MOD((HEX2DEC('Leaf Green Seeds'!E4) - 8 ),65536),4),"") -> ECBC | F4: =IFERROR(DEC2HEX(MOD((HEX2DEC('Leaf Green Seeds'!F4) + 3 ),65536),4),"") -> ECC9 | G4: =IFERROR(DEC2HEX(MOD((HEX2DEC('Leaf Green Seeds'!G4) - 18 ),65536),4),"") -> ECB3 | H4: =IFERROR(DEC2HEX(MOD((HEX2DEC('Leaf Green Seeds'!H4) - 8 ),65536),4),"") -> ECB4 | I4: =IFERROR(DEC2HEX(MOD((HEX2DEC('Leaf Green Seeds'!I4) + 3 ),65536),4),"") -> ECC0 | J4: =IFERROR(DEC2HEX(MOD((HEX2DEC('Leaf Green Seeds'!J4) - 18 ),65536),4),"") -> ECAB | K4: =IFERROR(DEC2HEX(MOD((HEX2DEC('Leaf Green Seeds'!K4) - 8 ),65536),4),"") -> ECAC | L4: =IFERROR(DEC2HEX(MOD((HEX2DEC('Leaf Green Seeds'!L4) + 3 ),65536),4),"") -> ECB8 | M4: =IFERROR(DEC2HEX(MOD((HEX2DEC('Leaf Green Seeds'!M4) - 18 ),65536),4),"") -> ECB4 | N4: =IFERROR(DEC2HEX(MOD((HEX2DEC('Leaf Green Seeds'!N4) - 8 ),65536),4),"") -> ECB7 | O4: =IFERROR(DEC2HEX(MOD((HEX2DEC('Leaf Green Seeds'!O4) + 3 ),65536),4),"") -> ECB8 | P4: =IFERROR(DEC2HEX(MOD((HEX2DEC('Leaf Green Seeds'!P4) - 8 ),65536),4),"") -> ECB4 | Q4: =IFERROR(DEC2HEX(MOD((HEX2DEC('Leaf Green Seeds'!Q4) - 8 ),65536),4),"") -> ECBA
A5: 3 | B5: 33784 | C5: 34780 | D5: =IFERROR(DEC2HEX(MOD((HEX2DEC('Leaf Green Seeds'!D5) - 18 ),65536),4),"") -> 36A3 | E5: =IFERROR(DEC2HEX(MOD((HEX2DEC('Leaf Green Seeds'!E5) - 8 ),65536),4),"") -> 369F | F5: =IFERROR(DEC2HEX(MOD((HEX2DEC('Leaf Green Seeds'!F5) + 3 ),65536),4),"") -> 36AB | G5: =IFERROR(DEC2HEX(MOD((HEX2DEC('Leaf Green Seeds'!G5) - 18 ),65536),4),"") -> 36BC | H5: =IFERROR(DEC2HEX(MOD((HEX2DEC('Leaf Green Seeds'!H5) - 8 ),65536),4),"") -> 36C7 | I5: =IFERROR(DEC2HEX(MOD((HEX2DEC('Leaf Green Seeds'!I5) + 3 ),65536),4),"") -> 36D3 | J5: =IFERROR(DEC2HEX(MOD((HEX2DEC('Leaf Green Seeds'!J5) - 18 ),65536),4),"") -> 369B | K5: =IFERROR(DEC2HEX(MOD((HEX2DEC('Leaf Green Seeds'!K5) - 8 ),65536),4),"") -> 369C | L5: =IFERROR(DEC2HEX(MOD((HEX2DEC('Leaf Green Seeds'!L5) + 3 ),65536),4),"") -> 36A3 | M5: =IFERROR(DEC2HEX(MOD((HEX2DEC('Leaf Green Seeds'!M5) - 18 ),65536),4),"") -> 36B4 | N5: =IFERROR(DEC2HEX(MOD((HEX2DEC('Leaf Green Seeds'!N5) - 8 ),65536),4),"") -> 36BF | O5: =IFERROR(DEC2HEX(MOD((HEX2DEC('Leaf Green Seeds'!O5) + 3 ),65536),4),"") -> 36C1 | P5: =IFERROR(DEC2HEX(MOD((HEX2DEC('Leaf Green Seeds'!P5) - 8 ),65536),4),"") -> 36A1 | Q5: =IFERROR(DEC2HEX(MOD((HEX2DEC('Leaf Green Seeds'!Q5) - 8 ),65536),4),"") -> 36BA
A6: 4 | B6: 33808 | C6: 34804 | D6: =IFERROR(DEC2HEX(MOD((HEX2DEC('Leaf Green Seeds'!D6) - 18 ),65536),4),"") -> 7F31 | E6: =IFERROR(DEC2HEX(MOD((HEX2DEC('Leaf Green Seeds'!E6) - 8 ),65536),4),"") -> 7F3A | F6: =IFERROR(DEC2HEX(MOD((HEX2DEC('Leaf Green Seeds'!F6) + 3 ),65536),4),"") -> 7F47 | G6: =IFERROR(DEC2HEX(MOD((HEX2DEC('Leaf Green Seeds'!G6) - 18 ),65536),4),"") -> 7F31 | H6: =IFERROR(DEC2HEX(MOD((HEX2DEC('Leaf Green Seeds'!H6) - 8 ),65536),4),"") -> 7F3A | I6: =IFERROR(DEC2HEX(MOD((HEX2DEC('Leaf Green Seeds'!I6) + 3 ),65536),4),"") -> 7F47 | J6: =IFERROR(DEC2HEX(MOD((HEX2DEC('Leaf Green Seeds'!J6) - 18 ),65536),4),"") -> 7F32 | K6: =IFERROR(DEC2HEX(MOD((HEX2DEC('Leaf Green Seeds'!K6) - 8 ),65536),4),"") -> 7F32 | L6: =IFERROR(DEC2HEX(MOD((HEX2DEC('Leaf Green Seeds'!L6) + 3 ),65536),4),"") -> 7F3F | M6: =IFERROR(DEC2HEX(MOD((HEX2DEC('Leaf Green Seeds'!M6) - 18 ),65536),4),"") -> 7F32 | N6: =IFERROR(DEC2HEX(MOD((HEX2DEC('Leaf Green Seeds'!N6) - 8 ),65536),4),"") -> 7F32 | O6: =IFERROR(DEC2HEX(MOD((HEX2DEC('Leaf Green Seeds'!O6) + 3 ),65536),4),"") -> 7F36 | P6: =IFERROR(DEC2HEX(MOD((HEX2DEC('Leaf Green Seeds'!P6) - 8 ),65536),4),"") -> 7F2F | Q6: =IFERROR(DEC2HEX(MOD((HEX2DEC('Leaf Green Seeds'!Q6) - 8 ),65536),4),"") -> 7F38
A7: 5 | B7: 33824 | C7: 34820 | D7: =IFERROR(DEC2HEX(MOD((HEX2DEC('Leaf Green Seeds'!D7) - 18 ),65536),4),"") -> C926 | E7: =IFERROR(DEC2HEX(MOD((HEX2DEC('Leaf Green Seeds'!E7) - 8 ),65536),4),"") -> C924 | F7: =IFERROR(DEC2HEX(MOD((HEX2DEC('Leaf Green Seeds'!F7) + 3 ),65536),4),"") -> C932 | G7: =IFERROR(DEC2HEX(MOD((HEX2DEC('Leaf Green Seeds'!G7) - 18 ),65536),4),"") -> C949 | H7: =IFERROR(DEC2HEX(MOD((HEX2DEC('Leaf Green Seeds'!H7) - 8 ),65536),4),"") -> C93C | I7: =IFERROR(DEC2HEX(MOD((HEX2DEC('Leaf Green Seeds'!I7) + 3 ),65536),4),"") -> C954 | J7: =IFERROR(DEC2HEX(MOD((HEX2DEC('Leaf Green Seeds'!J7) - 18 ),65536),4),"") -> C91E | K7: =IFERROR(DEC2HEX(MOD((HEX2DEC('Leaf Green Seeds'!K7) - 8 ),65536),4),"") -> C91C | L7: =IFERROR(DEC2HEX(MOD((HEX2DEC('Leaf Green Seeds'!L7) + 3 ),65536),4),"") -> C923 | M7: =IFERROR(DEC2HEX(MOD((HEX2DEC('Leaf Green Seeds'!M7) - 18 ),65536),4),"") -> C93D | N7: =IFERROR(DEC2HEX(MOD((HEX2DEC('Leaf Green Seeds'!N7) - 8 ),65536),4),"") -> C934 | O7: =IFERROR(DEC2HEX(MOD((HEX2DEC('Leaf Green Seeds'!O7) + 3 ),65536),4),"") -> C940 | P7: =IFERROR(DEC2HEX(MOD((HEX2DEC('Leaf Green Seeds'!P7) - 8 ),65536),4),"") -> C921 | Q7: =IFERROR(DEC2HEX(MOD((HEX2DEC('Leaf Green Seeds'!Q7) - 8 ),65536),4),"") -> C943
A8: 6 | B8: 33840 | C8: 34836 | D8: =IFERROR(DEC2HEX(MOD((HEX2DEC('Leaf Green Seeds'!D8) - 18 ),65536),4),"") -> 11A5 | E8: =IFERROR(DEC2HEX(MOD((HEX2DEC('Leaf Green Seeds'!E8) - 8 ),65536),4),"") -> 11AD | F8: =IFERROR(DEC2HEX(MOD((HEX2DEC('Leaf Green Seeds'!F8) + 3 ),65536),4),"") -> 11B2 | G8: =IFERROR(DEC2HEX(MOD((HEX2DEC('Leaf Green Seeds'!G8) - 18 ),65536),4),"") -> 11A5 | H8: =IFERROR(DEC2HEX(MOD((HEX2DEC('Leaf Green Seeds'!H8) - 8 ),65536),4),"") -> 11A4 | I8: =IFERROR(DEC2HEX(MOD((HEX2DEC('Leaf Green Seeds'!I8) + 3 ),65536),4),"") -> 11B2 | J8: =IFERROR(DEC2HEX(MOD((HEX2DEC('Leaf Green Seeds'!J8) - 18 ),65536),4),"") -> 11A8 | K8: =IFERROR(DEC2HEX(MOD((HEX2DEC('Leaf Green Seeds'!K8) - 8 ),65536),4),"") -> 119C | L8: =IFERROR(DEC2HEX(MOD((HEX2DEC('Leaf Green Seeds'!L8) + 3 ),65536),4),"") -> 11B5 | M8: =IFERROR(DEC2HEX(MOD((HEX2DEC('Leaf Green Seeds'!M8) - 18 ),65536),4),"") -> 119C | N8: =IFERROR(DEC2HEX(MOD((HEX2DEC('Leaf Green Seeds'!N8) - 8 ),65536),4),"") -> 11A5 | O8: =IFERROR(DEC2HEX(MOD((HEX2DEC('Leaf Green Seeds'!O8) + 3 ),65536),4),"") -> 11A9 | P8: =IFERROR(DEC2HEX(MOD((HEX2DEC('Leaf Green Seeds'!P8) - 8 ),65536),4),"") -> 11A1 | Q8: =IFERROR(DEC2HEX(MOD((HEX2DEC('Leaf Green Seeds'!Q8) - 8 ),65536),4),"") -> 11AF
A9: 7 | B9: 33856 | C9: 34852 | D9: =IFERROR(DEC2HEX(MOD((HEX2DEC('Leaf Green Seeds'!D9) - 18 ),65536),4),"") -> 3FBA | E9: =IFERROR(DEC2HEX(MOD((HEX2DEC('Leaf Green Seeds'!E9) - 8 ),65536),4),"") -> 3FBA | F9: =IFERROR(DEC2HEX(MOD((HEX2DEC('Leaf Green Seeds'!F9) + 3 ),65536),4),"") -> 3FC7 | G9: =IFERROR(DEC2HEX(MOD((HEX2DEC('Leaf Green Seeds'!G9) - 18 ),65536),4),"") -> 3FD8 | H9: =IFERROR(DEC2HEX(MOD((HEX2DEC('Leaf Green Seeds'!H9) - 8 ),65536),4),"") -> 3FD9 | I9: =IFERROR(DEC2HEX(MOD((HEX2DEC('Leaf Green Seeds'!I9) + 3 ),65536),4),"") -> 3FE5 | J9: =IFERROR(DEC2HEX(MOD((HEX2DEC('Leaf Green Seeds'!J9) - 18 ),65536),4),"") -> 3FA6 | K9: =IFERROR(DEC2HEX(MOD((HEX2DEC('Leaf Green Seeds'!K9) - 8 ),65536),4),"") -> 3FA7 | L9: =IFERROR(DEC2HEX(MOD((HEX2DEC('Leaf Green Seeds'!L9) + 3 ),65536),4),"") -> 3FBE | M9: =IFERROR(DEC2HEX(MOD((HEX2DEC('Leaf Green Seeds'!M9) - 18 ),65536),4),"") -> 3FC5 | N9: =IFERROR(DEC2HEX(MOD((HEX2DEC('Leaf Green Seeds'!N9) - 8 ),65536),4),"") -> 3FD1 | O9: =IFERROR(DEC2HEX(MOD((HEX2DEC('Leaf Green Seeds'!O9) + 3 ),65536),4),"") -> 3FDC | P9: =IFERROR(DEC2HEX(MOD((HEX2DEC('Leaf Green Seeds'!P9) - 8 ),65536),4),"") -> 3FB7 | Q9: =IFERROR(DEC2HEX(MOD((HEX2DEC('Leaf Green Seeds'!Q9) - 8 ),65536),4),"") -> 3FD5
A10: 8 | B10: 33872 | C10: 34868 | D10: =IFERROR(DEC2HEX(MOD((HEX2DEC('Leaf Green Seeds'!D10) - 18 ),65536),4),"") -> 96CC | E10: =IFERROR(DEC2HEX(MOD((HEX2DEC('Leaf Green Seeds'!E10) - 8 ),65536),4),"") -> 96CD | F10: =IFERROR(DEC2HEX(MOD((HEX2DEC('Leaf Green Seeds'!F10) + 3 ),65536),4),"") -> 96E1 | G10: =IFERROR(DEC2HEX(MOD((HEX2DEC('Leaf Green Seeds'!G10) - 18 ),65536),4),"") -> 96F2 | H10: =IFERROR(DEC2HEX(MOD((HEX2DEC('Leaf Green Seeds'!H10) - 8 ),65536),4),"") -> 96F6 | I10: =IFERROR(DEC2HEX(MOD((HEX2DEC('Leaf Green Seeds'!I10) + 3 ),65536),4),"") -> 96FF | J10: =IFERROR(DEC2HEX(MOD((HEX2DEC('Leaf Green Seeds'!J10) - 18 ),65536),4),"") -> 96CC | K10: =IFERROR(DEC2HEX(MOD((HEX2DEC('Leaf Green Seeds'!K10) - 8 ),65536),4),"") -> 96CF | L10: =IFERROR(DEC2HEX(MOD((HEX2DEC('Leaf Green Seeds'!L10) + 3 ),65536),4),"") -> 96DC | M10: =IFERROR(DEC2HEX(MOD((HEX2DEC('Leaf Green Seeds'!M10) - 18 ),65536),4),"") -> 96E2 | N10: =IFERROR(DEC2HEX(MOD((HEX2DEC('Leaf Green Seeds'!N10) - 8 ),65536),4),"") -> 96EB | O10: =IFERROR(DEC2HEX(MOD((HEX2DEC('Leaf Green Seeds'!O10) + 3 ),65536),4),"") -> 96FA | P10: =IFERROR(DEC2HEX(MOD((HEX2DEC('Leaf Green Seeds'!P10) - 8 ),65536),4),"") -> 96D4 | Q10: =IFERROR(DEC2HEX(MOD((HEX2DEC('Leaf Green Seeds'!Q10) - 8 ),65536),4),"") -> 96F0
A11: 9 | B11: 33888 | C11: 34884 | D11: =IFERROR(DEC2HEX(MOD((HEX2DEC('Leaf Green Seeds'!D11) - 18 ),65536),4),"") -> D4B7 | E11: =IFERROR(DEC2HEX(MOD((HEX2DEC('Leaf Green Seeds'!E11) - 8 ),65536),4),"") -> D4B8 | F11: =IFERROR(DEC2HEX(MOD((HEX2DEC('Leaf Green Seeds'!F11) + 3 ),65536),4),"") -> D4CD | G11: =IFERROR(DEC2HEX(MOD((HEX2DEC('Leaf Green Seeds'!G11) - 18 ),65536),4),"") -> D4B7 | H11: =IFERROR(DEC2HEX(MOD((HEX2DEC('Leaf Green Seeds'!H11) - 8 ),65536),4),"") -> D4B8 | I11: =IFERROR(DEC2HEX(MOD((HEX2DEC('Leaf Green Seeds'!I11) + 3 ),65536),4),"") -> D4C4 | J11: =IFERROR(DEC2HEX(MOD((HEX2DEC('Leaf Green Seeds'!J11) - 18 ),65536),4),"") -> D4AF | K11: =IFERROR(DEC2HEX(MOD((HEX2DEC('Leaf Green Seeds'!K11) - 8 ),65536),4),"") -> D4B8 | L11: =IFERROR(DEC2HEX(MOD((HEX2DEC('Leaf Green Seeds'!L11) + 3 ),65536),4),"") -> D4BC | M11: =IFERROR(DEC2HEX(MOD((HEX2DEC('Leaf Green Seeds'!M11) - 18 ),65536),4),"") -> D4B7 | N11: =IFERROR(DEC2HEX(MOD((HEX2DEC('Leaf Green Seeds'!N11) - 8 ),65536),4),"") -> D4B0 | O11: =IFERROR(DEC2HEX(MOD((HEX2DEC('Leaf Green Seeds'!O11) + 3 ),65536),4),"") -> D4BC | P11: =IFERROR(DEC2HEX(MOD((HEX2DEC('Leaf Green Seeds'!P11) - 8 ),65536),4),"") -> D4B5 | Q11: =IFERROR(DEC2HEX(MOD((HEX2DEC('Leaf Green Seeds'!Q11) - 8 ),65536),4),"") -> D4B5
A12: 10 | B12: 33904 | C12: 34900 | D12: =IFERROR(DEC2HEX(MOD((HEX2DEC('Leaf Green Seeds'!D12) - 18 ),65536),4),"") -> 1E84 | E12: =IFERROR(DEC2HEX(MOD((HEX2DEC('Leaf Green Seeds'!E12) - 8 ),65536),4),"") -> 1E85 | F12: =IFERROR(DEC2HEX(MOD((HEX2DEC('Leaf Green Seeds'!F12) + 3 ),65536),4),"") -> 1E9B | G12: =IFERROR(DEC2HEX(MOD((HEX2DEC('Leaf Green Seeds'!G12) - 18 ),65536),4),"") -> 1EA3 | H12: =IFERROR(DEC2HEX(MOD((HEX2DEC('Leaf Green Seeds'!H12) - 8 ),65536),4),"") -> 1EA4 | I12: =IFERROR(DEC2HEX(MOD((HEX2DEC('Leaf Green Seeds'!I12) + 3 ),65536),4),"") -> 1EB9 | J12: =IFERROR(DEC2HEX(MOD((HEX2DEC('Leaf Green Seeds'!J12) - 18 ),65536),4),"") -> 1E7C | K12: =IFERROR(DEC2HEX(MOD((HEX2DEC('Leaf Green Seeds'!K12) - 8 ),65536),4),"") -> 1E7D | L12: =IFERROR(DEC2HEX(MOD((HEX2DEC('Leaf Green Seeds'!L12) + 3 ),65536),4),"") -> 1E93 | M12: =IFERROR(DEC2HEX(MOD((HEX2DEC('Leaf Green Seeds'!M12) - 18 ),65536),4),"") -> 1EA4 | N12: =IFERROR(DEC2HEX(MOD((HEX2DEC('Leaf Green Seeds'!N12) - 8 ),65536),4),"") -> 1E9C | O12: =IFERROR(DEC2HEX(MOD((HEX2DEC('Leaf Green Seeds'!O12) + 3 ),65536),4),"") -> 1EB1 | P12: =IFERROR(DEC2HEX(MOD((HEX2DEC('Leaf Green Seeds'!P12) - 8 ),65536),4),"") -> 1E8C | Q12: =IFERROR(DEC2HEX(MOD((HEX2DEC('Leaf Green Seeds'!Q12) - 8 ),65536),4),"") -> 1EA1
A13: 11 | B13: 33920 | C13: 34916 | D13: =IFERROR(DEC2HEX(MOD((HEX2DEC('Leaf Green Seeds'!D13) - 18 ),65536),4),"") -> 9231 | E13: =IFERROR(DEC2HEX(MOD((HEX2DEC('Leaf Green Seeds'!E13) - 8 ),65536),4),"") -> 922A | F13: =IFERROR(DEC2HEX(MOD((HEX2DEC('Leaf Green Seeds'!F13) + 3 ),65536),4),"") -> 9240 | G13: =IFERROR(DEC2HEX(MOD((HEX2DEC('Leaf Green Seeds'!G13) - 18 ),65536),4),"") -> 9231 | H13: =IFERROR(DEC2HEX(MOD((HEX2DEC('Leaf Green Seeds'!H13) - 8 ),65536),4),"") -> 9232 | I13: =IFERROR(DEC2HEX(MOD((HEX2DEC('Leaf Green Seeds'!I13) + 3 ),65536),4),"") -> 923E | J13: =IFERROR(DEC2HEX(MOD((HEX2DEC('Leaf Green Seeds'!J13) - 18 ),65536),4),"") -> 9221 | K13: =IFERROR(DEC2HEX(MOD((HEX2DEC('Leaf Green Seeds'!K13) - 8 ),65536),4),"") -> 922A | L13: =IFERROR(DEC2HEX(MOD((HEX2DEC('Leaf Green Seeds'!L13) + 3 ),65536),4),"") -> 922E | M13: =IFERROR(DEC2HEX(MOD((HEX2DEC('Leaf Green Seeds'!M13) - 18 ),65536),4),"") -> 9229 | N13: =IFERROR(DEC2HEX(MOD((HEX2DEC('Leaf Green Seeds'!N13) - 8 ),65536),4),"") -> 9222 | O13: =IFERROR(DEC2HEX(MOD((HEX2DEC('Leaf Green Seeds'!O13) + 3 ),65536),4),"") -> 922E | P13: =IFERROR(DEC2HEX(MOD((HEX2DEC('Leaf Green Seeds'!P13) - 8 ),65536),4),"") -> 9227 | Q13: =IFERROR(DEC2HEX(MOD((HEX2DEC('Leaf Green Seeds'!Q13) - 8 ),65536),4),"") -> 9227
A14: 12 | B14: 33936 | C14: 34932 | D14: =IFERROR(DEC2HEX(MOD((HEX2DEC('Leaf Green Seeds'!D14) - 18 ),65536),4),"") -> CF02 | E14: =IFERROR(DEC2HEX(MOD((HEX2DEC('Leaf Green Seeds'!E14) - 8 ),65536),4),"") -> CEFC | F14: =IFERROR(DEC2HEX(MOD((HEX2DEC('Leaf Green Seeds'!F14) + 3 ),65536),4),"") -> CF08 | G14: =IFERROR(DEC2HEX(MOD((HEX2DEC('Leaf Green Seeds'!G14) - 18 ),65536),4),"") -> CF1E | H14: =IFERROR(DEC2HEX(MOD((HEX2DEC('Leaf Green Seeds'!H14) - 8 ),65536),4),"") -> CF13 | I14: =IFERROR(DEC2HEX(MOD((HEX2DEC('Leaf Green Seeds'!I14) + 3 ),65536),4),"") -> CF1F | J14: =IFERROR(DEC2HEX(MOD((HEX2DEC('Leaf Green Seeds'!J14) - 18 ),65536),4),"") -> CEFC | K14: =IFERROR(DEC2HEX(MOD((HEX2DEC('Leaf Green Seeds'!K14) - 8 ),65536),4),"") -> CEF4 | L14: =IFERROR(DEC2HEX(MOD((HEX2DEC('Leaf Green Seeds'!L14) + 3 ),65536),4),"") -> CF0A | M14: =IFERROR(DEC2HEX(MOD((HEX2DEC('Leaf Green Seeds'!M14) - 18 ),65536),4),"") -> CF15 | N14: =IFERROR(DEC2HEX(MOD((HEX2DEC('Leaf Green Seeds'!N14) - 8 ),65536),4),"") -> CF13 | O14: =IFERROR(DEC2HEX(MOD((HEX2DEC('Leaf Green Seeds'!O14) + 3 ),65536),4),"") -> CF1F | P14: =IFERROR(DEC2HEX(MOD((HEX2DEC('Leaf Green Seeds'!P14) - 8 ),65536),4),"") -> CEF9 | Q14: =IFERROR(DEC2HEX(MOD((HEX2DEC('Leaf Green Seeds'!Q14) - 8 ),65536),4),"") -> CF10
... A2440: 2438 | B2440: 74638 | C2440: 75632 | D2440: =IFERROR(DEC2HEX(MOD((HEX2DEC('Leaf Green Seeds'!D2440) - 18 ),65536),4),"") -> BC98 | E2440: =IFERROR(DEC2HEX(MOD((HEX2DEC('Leaf Green Seeds'!E2440) - 8 ),65536),4),"") -> BC9A | F2440: =IFERROR(DEC2HEX(MOD((HEX2DEC('Leaf Green Seeds'!F2440) + 3 ),65536),4),"") -> BCA5 | G2440: =IFERROR(DEC2HEX(MOD((HEX2DEC('Leaf Green Seeds'!G2440) - 18 ),65536),4),"") -> BCB5 | H2440: =IFERROR(DEC2HEX(MOD((HEX2DEC('Leaf Green Seeds'!H2440) - 8 ),65536),4),"") -> BCB6 | I2440: =IFERROR(DEC2HEX(MOD((HEX2DEC('Leaf Green Seeds'!I2440) + 3 ),65536),4),"") -> BCBB | J2440: =IFERROR(DEC2HEX(MOD((HEX2DEC('Leaf Green Seeds'!J2440) - 18 ),65536),4),"") | K2440: =IFERROR(DEC2HEX(MOD((HEX2DEC('Leaf Green Seeds'!K2440) - 8 ),65536),4),"") | L2440: =IFERROR(DEC2HEX(MOD((HEX2DEC('Leaf Green Seeds'!L2440) + 3 ),65536),4),"") | M2440: =IFERROR(DEC2HEX(MOD((HEX2DEC('Leaf Green Seeds'!M2440) - 18 ),65536),4),"") | N2440: =IFERROR(DEC2HEX(MOD((HEX2DEC('Leaf Green Seeds'!N2440) - 8 ),65536),4),"") | O2440: =IFERROR(DEC2HEX(MOD((HEX2DEC('Leaf Green Seeds'!O2440) + 3 ),65536),4),"") -> BCBD | P2440: =IFERROR(DEC2HEX(MOD((HEX2DEC('Leaf Green Seeds'!P2440) - 8 ),65536),4),"") -> BC8D | Q2440: =IFERROR(DEC2HEX(MOD((HEX2DEC('Leaf Green Seeds'!Q2440) - 8 ),65536),4),"") -> BCAC

Sheet Held Blackout R Button
A1: Hold the R Button during the black screen right before the shooting star from the intro appears. You can let go of it as soon you can see the leaves on the title screen. | J1: Instead of pressing the A button on the title screen, press Start instead | P1: Instead of pressing the A button on the title screen, press L instead
A2: # | B2: Intro Time ms (GBA) | C2: Intro Time ms (NDS) | D2: MONO/LR | E2: MONO/L=A | F2: MONO/HELP | G2: STEREO/LR | H2: STEREO/L=A | I2: STEREO/HELP | J2: MONO/LR, Start | K2: MONO/L=A, Start | L2: MONO/HELP, Start | M2: STEREO/LR, Start | N2: STEREO/L=A, Start | O2: STEREO/HELP, Start | P2: MONO/L=A, L | Q2: STEREO/L=A, L
A3: 1 | B3: 33752 | C3: 34748 | D3: =IFERROR(DEC2HEX(MOD((HEX2DEC('Leaf Green Seeds'!D3) - 23 ),65536),4),"") -> A071 | E3: =IFERROR(DEC2HEX(MOD((HEX2DEC('Leaf Green Seeds'!E3) - 23 ),65536),4),"") -> A05E | F3: =IFERROR(DEC2HEX(MOD((HEX2DEC('Leaf Green Seeds'!F3) - 23 ),65536),4),"") -> A069 | G3: =IFERROR(DEC2HEX(MOD((HEX2DEC('Leaf Green Seeds'!G3) - 23 ),65536),4),"") -> A09C | H3: =IFERROR(DEC2HEX(MOD((HEX2DEC('Leaf Green Seeds'!H3) - 23 ),65536),4),"") -> A0A0 | I3: =IFERROR(DEC2HEX(MOD((HEX2DEC('Leaf Green Seeds'!I3) - 23 ),65536),4),"") -> A094 | J3: =IFERROR(DEC2HEX(MOD((HEX2DEC('Leaf Green Seeds'!J3) - 23 ),65536),4),"") -> A067 | K3: =IFERROR(DEC2HEX(MOD((HEX2DEC('Leaf Green Seeds'!K3) - 23 ),65536),4),"") -> A060 | ... Q3: =IFERROR(DEC2HEX(MOD((HEX2DEC('Leaf Green Seeds'!Q3) - 23 ),65536),4),"") -> A09C
A4: 2 | B4: 33768 | C4: 34764 | D4: =IFERROR(DEC2HEX(MOD((HEX2DEC('Leaf Green Seeds'!D4) - 23 ),65536),4),"") -> ECB8 | E4: =IFERROR(DEC2HEX(MOD((HEX2DEC('Leaf Green Seeds'!E4) - 23 ),65536),4),"") -> ECAD | F4: =IFERROR(DEC2HEX(MOD((HEX2DEC('Leaf Green Seeds'!F4) - 23 ),65536),4),"") -> ECAF | G4: =IFERROR(DEC2HEX(MOD((HEX2DEC('Leaf Green Seeds'!G4) - 23 ),65536),4),"") -> ECAE | H4: =IFERROR(DEC2HEX(MOD((HEX2DEC('Leaf Green Seeds'!H4) - 23 ),65536),4),"") -> ECA5 | I4: =IFERROR(DEC2HEX(MOD((HEX2DEC('Leaf Green Seeds'!I4) - 23 ),65536),4),"") -> ECA6 | J4: =IFERROR(DEC2HEX(MOD((HEX2DEC('Leaf Green Seeds'!J4) - 23 ),65536),4),"") -> ECA6 | K4: =IFERROR(DEC2HEX(MOD((HEX2DEC('Leaf Green Seeds'!K4) - 23 ),65536),4),"") -> EC9D | ... Q4: =IFERROR(DEC2HEX(MOD((HEX2DEC('Leaf Green Seeds'!Q4) - 23 ),65536),4),"") -> ECAB
A5: 3 | B5: 33784 | C5: 34780 | D5: =IFERROR(DEC2HEX(MOD((HEX2DEC('Leaf Green Seeds'!D5) - 23 ),65536),4),"") -> 369E | E5: =IFERROR(DEC2HEX(MOD((HEX2DEC('Leaf Green Seeds'!E5) - 23 ),65536),4),"") -> 3690 | F5: =IFERROR(DEC2HEX(MOD((HEX2DEC('Leaf Green Seeds'!F5) - 23 ),65536),4),"") -> 3691 | G5: =IFERROR(DEC2HEX(MOD((HEX2DEC('Leaf Green Seeds'!G5) - 23 ),65536),4),"") -> 36B7 | H5: =IFERROR(DEC2HEX(MOD((HEX2DEC('Leaf Green Seeds'!H5) - 23 ),65536),4),"") -> 36B8 | I5: =IFERROR(DEC2HEX(MOD((HEX2DEC('Leaf Green Seeds'!I5) - 23 ),65536),4),"") -> 36B9 | J5: =IFERROR(DEC2HEX(MOD((HEX2DEC('Leaf Green Seeds'!J5) - 23 ),65536),4),"") -> 3696 | K5: =IFERROR(DEC2HEX(MOD((HEX2DEC('Leaf Green Seeds'!K5) - 23 ),65536),4),"") -> 368D | ... Q5: =IFERROR(DEC2HEX(MOD((HEX2DEC('Leaf Green Seeds'!Q5) - 23 ),65536),4),"") -> 36AB
A6: 4 | B6: 33808 | C6: 34804 | D6: =IFERROR(DEC2HEX(MOD((HEX2DEC('Leaf Green Seeds'!D6) - 23 ),65536),4),"") -> 7F2C | E6: =IFERROR(DEC2HEX(MOD((HEX2DEC('Leaf Green Seeds'!E6) - 23 ),65536),4),"") -> 7F2B | F6: =IFERROR(DEC2HEX(MOD((HEX2DEC('Leaf Green Seeds'!F6) - 23 ),65536),4),"") -> 7F2D | G6: =IFERROR(DEC2HEX(MOD((HEX2DEC('Leaf Green Seeds'!G6) - 23 ),65536),4),"") -> 7F2C | H6: =IFERROR(DEC2HEX(MOD((HEX2DEC('Leaf Green Seeds'!H6) - 23 ),65536),4),"") -> 7F2B | I6: =IFERROR(DEC2HEX(MOD((HEX2DEC('Leaf Green Seeds'!I6) - 23 ),65536),4),"") -> 7F2D | J6: =IFERROR(DEC2HEX(MOD((HEX2DEC('Leaf Green Seeds'!J6) - 23 ),65536),4),"") -> 7F2D | K6: =IFERROR(DEC2HEX(MOD((HEX2DEC('Leaf Green Seeds'!K6) - 23 ),65536),4),"") -> 7F23 | ... Q6: =IFERROR(DEC2HEX(MOD((HEX2DEC('Leaf Green Seeds'!Q6) - 23 ),65536),4),"") -> 7F29
A7: 5 | B7: 33824 | C7: 34820 | D7: =IFERROR(DEC2HEX(MOD((HEX2DEC('Leaf Green Seeds'!D7) - 23 ),65536),4),"") -> C921 | E7: =IFERROR(DEC2HEX(MOD((HEX2DEC('Leaf Green Seeds'!E7) - 23 ),65536),4),"") -> C915 | F7: =IFERROR(DEC2HEX(MOD((HEX2DEC('Leaf Green Seeds'!F7) - 23 ),65536),4),"") -> C918 | G7: =IFERROR(DEC2HEX(MOD((HEX2DEC('Leaf Green Seeds'!G7) - 23 ),65536),4),"") -> C944 | H7: =IFERROR(DEC2HEX(MOD((HEX2DEC('Leaf Green Seeds'!H7) - 23 ),65536),4),"") -> C92D | I7: =IFERROR(DEC2HEX(MOD((HEX2DEC('Leaf Green Seeds'!I7) - 23 ),65536),4),"") -> C93A | J7: =IFERROR(DEC2HEX(MOD((HEX2DEC('Leaf Green Seeds'!J7) - 23 ),65536),4),"") -> C919 | K7: =IFERROR(DEC2HEX(MOD((HEX2DEC('Leaf Green Seeds'!K7) - 23 ),65536),4),"") -> C90D | ... Q7: =IFERROR(DEC2HEX(MOD((HEX2DEC('Leaf Green Seeds'!Q7) - 23 ),65536),4),"") -> C934
A8: 6 | B8: 33840 | C8: 34836 | D8: =IFERROR(DEC2HEX(MOD((HEX2DEC('Leaf Green Seeds'!D8) - 23 ),65536),4),"") -> 11A0 | E8: =IFERROR(DEC2HEX(MOD((HEX2DEC('Leaf Green Seeds'!E8) - 23 ),65536),4),"") -> 119E | F8: =IFERROR(DEC2HEX(MOD((HEX2DEC('Leaf Green Seeds'!F8) - 23 ),65536),4),"") -> 1198 | G8: =IFERROR(DEC2HEX(MOD((HEX2DEC('Leaf Green Seeds'!G8) - 23 ),65536),4),"") -> 11A0 | H8: =IFERROR(DEC2HEX(MOD((HEX2DEC('Leaf Green Seeds'!H8) - 23 ),65536),4),"") -> 1195 | I8: =IFERROR(DEC2HEX(MOD((HEX2DEC('Leaf Green Seeds'!I8) - 23 ),65536),4),"") -> 1198 | J8: =IFERROR(DEC2HEX(MOD((HEX2DEC('Leaf Green Seeds'!J8) - 23 ),65536),4),"") -> 11A3 | K8: =IFERROR(DEC2HEX(MOD((HEX2DEC('Leaf Green Seeds'!K8) - 23 ),65536),4),"") -> 118D | ... Q8: =IFERROR(DEC2HEX(MOD((HEX2DEC('Leaf Green Seeds'!Q8) - 23 ),65536),4),"") -> 11A0
A9: 7 | B9: 33856 | C9: 34852 | D9: =IFERROR(DEC2HEX(MOD((HEX2DEC('Leaf Green Seeds'!D9) - 23 ),65536),4),"") -> 3FB5 | E9: =IFERROR(DEC2HEX(MOD((HEX2DEC('Leaf Green Seeds'!E9) - 23 ),65536),4),"") -> 3FAB | F9: =IFERROR(DEC2HEX(MOD((HEX2DEC('Leaf Green Seeds'!F9) - 23 ),65536),4),"") -> 3FAD | G9: =IFERROR(DEC2HEX(MOD((HEX2DEC('Leaf Green Seeds'!G9) - 23 ),65536),4),"") -> 3FD3 | H9: =IFERROR(DEC2HEX(MOD((HEX2DEC('Leaf Green Seeds'!H9) - 23 ),65536),4),"") -> 3FCA | I9: =IFERROR(DEC2HEX(MOD((HEX2DEC('Leaf Green Seeds'!I9) - 23 ),65536),4),"") -> 3FCB | J9: =IFERROR(DEC2HEX(MOD((HEX2DEC('Leaf Green Seeds'!J9) - 23 ),65536),4),"") -> 3FA1 | K9: =IFERROR(DEC2HEX(MOD((HEX2DEC('Leaf Green Seeds'!K9) - 23 ),65536),4),"") -> 3F98 | ... Q9: =IFERROR(DEC2HEX(MOD((HEX2DEC('Leaf Green Seeds'!Q9) - 23 ),65536),4),"") -> 3FC6
A10: 8 | B10: 33872 | C10: 34868 | D10: =IFERROR(DEC2HEX(MOD((HEX2DEC('Leaf Green Seeds'!D10) - 23 ),65536),4),"") -> 96C7 | E10: =IFERROR(DEC2HEX(MOD((HEX2DEC('Leaf Green Seeds'!E10) - 23 ),65536),4),"") -> 96BE | F10: =IFERROR(DEC2HEX(MOD((HEX2DEC('Leaf Green Seeds'!F10) - 23 ),65536),4),"") -> 96C7 | G10: =IFERROR(DEC2HEX(MOD((HEX2DEC('Leaf Green Seeds'!G10) - 23 ),65536),4),"") -> 96ED | H10: =IFERROR(DEC2HEX(MOD((HEX2DEC('Leaf Green Seeds'!H10) - 23 ),65536),4),"") -> 96E7 | I10: =IFERROR(DEC2HEX(MOD((HEX2DEC('Leaf Green Seeds'!I10) - 23 ),65536),4),"") -> 96E5 | J10: =IFERROR(DEC2HEX(MOD((HEX2DEC('Leaf Green Seeds'!J10) - 23 ),65536),4),"") -> 96C7 | K10: =IFERROR(DEC2HEX(MOD((HEX2DEC('Leaf Green Seeds'!K10) - 23 ),65536),4),"") -> 96C0 | ... Q10: =IFERROR(DEC2HEX(MOD((HEX2DEC('Leaf Green Seeds'!Q10) - 23 ),65536),4),"") -> 96E1
A11: 9 | B11: 33888 | C11: 34884 | D11: =IFERROR(DEC2HEX(MOD((HEX2DEC('Leaf Green Seeds'!D11) - 23 ),65536),4),"") -> D4B2 | E11: =IFERROR(DEC2HEX(MOD((HEX2DEC('Leaf Green Seeds'!E11) - 23 ),65536),4),"") -> D4A9 | F11: =IFERROR(DEC2HEX(MOD((HEX2DEC('Leaf Green Seeds'!F11) - 23 ),65536),4),"") -> D4B3 | G11: =IFERROR(DEC2HEX(MOD((HEX2DEC('Leaf Green Seeds'!G11) - 23 ),65536),4),"") -> D4B2 | H11: =IFERROR(DEC2HEX(MOD((HEX2DEC('Leaf Green Seeds'!H11) - 23 ),65536),4),"") -> D4A9 | I11: =IFERROR(DEC2HEX(MOD((HEX2DEC('Leaf Green Seeds'!I11) - 23 ),65536),4),"") -> D4AA | J11: =IFERROR(DEC2HEX(MOD((HEX2DEC('Leaf Green Seeds'!J11) - 23 ),65536),4),"") -> D4AA | K11: =IFERROR(DEC2HEX(MOD((HEX2DEC('Leaf Green Seeds'!K11) - 23 ),65536),4),"") -> D4A9 | ... Q11: =IFERROR(DEC2HEX(MOD((HEX2DEC('Leaf Green Seeds'!Q11) - 23 ),65536),4),"") -> D4A6
A12: 10 | B12: 33904 | C12: 34900 | D12: =IFERROR(DEC2HEX(MOD((HEX2DEC('Leaf Green Seeds'!D12) - 23 ),65536),4),"") -> 1E7F | E12: =IFERROR(DEC2HEX(MOD((HEX2DEC('Leaf Green Seeds'!E12) - 23 ),65536),4),"") -> 1E76 | F12: =IFERROR(DEC2HEX(MOD((HEX2DEC('Leaf Green Seeds'!F12) - 23 ),65536),4),"") -> 1E81 | G12: =IFERROR(DEC2HEX(MOD((HEX2DEC('Leaf Green Seeds'!G12) - 23 ),65536),4),"") -> 1E9E | H12: =IFERROR(DEC2HEX(MOD((HEX2DEC('Leaf Green Seeds'!H12) - 23 ),65536),4),"") -> 1E95 | I12: =IFERROR(DEC2HEX(MOD((HEX2DEC('Leaf Green Seeds'!I12) - 23 ),65536),4),"") -> 1E9F | J12: =IFERROR(DEC2HEX(MOD((HEX2DEC('Leaf Green Seeds'!J12) - 23 ),65536),4),"") -> 1E77 | K12: =IFERROR(DEC2HEX(MOD((HEX2DEC('Leaf Green Seeds'!K12) - 23 ),65536),4),"") -> 1E6E | ... Q12: =IFERROR(DEC2HEX(MOD((HEX2DEC('Leaf Green Seeds'!Q12) - 23 ),65536),4),"") -> 1E92
A13: 11 | B13: 33920 | C13: 34916 | D13: =IFERROR(DEC2HEX(MOD((HEX2DEC('Leaf Green Seeds'!D13) - 23 ),65536),4),"") -> 922C | E13: =IFERROR(DEC2HEX(MOD((HEX2DEC('Leaf Green Seeds'!E13) - 23 ),65536),4),"") -> 921B | F13: =IFERROR(DEC2HEX(MOD((HEX2DEC('Leaf Green Seeds'!F13) - 23 ),65536),4),"") -> 9226 | G13: =IFERROR(DEC2HEX(MOD((HEX2DEC('Leaf Green Seeds'!G13) - 23 ),65536),4),"") -> 922C | H13: =IFERROR(DEC2HEX(MOD((HEX2DEC('Leaf Green Seeds'!H13) - 23 ),65536),4),"") -> 9223 | I13: =IFERROR(DEC2HEX(MOD((HEX2DEC('Leaf Green Seeds'!I13) - 23 ),65536),4),"") -> 9224 | J13: =IFERROR(DEC2HEX(MOD((HEX2DEC('Leaf Green Seeds'!J13) - 23 ),65536),4),"") -> 921C | K13: =IFERROR(DEC2HEX(MOD((HEX2DEC('Leaf Green Seeds'!K13) - 23 ),65536),4),"") -> 921B | ... Q13: =IFERROR(DEC2HEX(MOD((HEX2DEC('Leaf Green Seeds'!Q13) - 23 ),65536),4),"") -> 9218
A14: 12 | B14: 33936 | C14: 34932 | D14: =IFERROR(DEC2HEX(MOD((HEX2DEC('Leaf Green Seeds'!D14) - 23 ),65536),4),"") -> CEFD | E14: =IFERROR(DEC2HEX(MOD((HEX2DEC('Leaf Green Seeds'!E14) - 23 ),65536),4),"") -> CEED | F14: =IFERROR(DEC2HEX(MOD((HEX2DEC('Leaf Green Seeds'!F14) - 23 ),65536),4),"") -> CEEE | G14: =IFERROR(DEC2HEX(MOD((HEX2DEC('Leaf Green Seeds'!G14) - 23 ),65536),4),"") -> CF19 | H14: =IFERROR(DEC2HEX(MOD((HEX2DEC('Leaf Green Seeds'!H14) - 23 ),65536),4),"") -> CF04 | I14: =IFERROR(DEC2HEX(MOD((HEX2DEC('Leaf Green Seeds'!I14) - 23 ),65536),4),"") -> CF05 | J14: =IFERROR(DEC2HEX(MOD((HEX2DEC('Leaf Green Seeds'!J14) - 23 ),65536),4),"") -> CEF7 | K14: =IFERROR(DEC2HEX(MOD((HEX2DEC('Leaf Green Seeds'!K14) - 23 ),65536),4),"") -> CEE5 | ... Q14: =IFERROR(DEC2HEX(MOD((HEX2DEC('Leaf Green Seeds'!Q14) - 23 ),65536),4),"") -> CF01
... A2440: 2438 | B2440: 74638 | C2440: 75632 | D2440: =IFERROR(DEC2HEX(MOD((HEX2DEC('Leaf Green Seeds'!D2440) - 23 ),65536),4),"") -> BC93 | E2440: =IFERROR(DEC2HEX(MOD((HEX2DEC('Leaf Green Seeds'!E2440) - 23 ),65536),4),"") -> BC8B | F2440: =IFERROR(DEC2HEX(MOD((HEX2DEC('Leaf Green Seeds'!F2440) - 23 ),65536),4),"") -> BC8B | G2440: =IFERROR(DEC2HEX(MOD((HEX2DEC('Leaf Green Seeds'!G2440) - 23 ),65536),4),"") -> BCB0 | H2440: =IFERROR(DEC2HEX(MOD((HEX2DEC('Leaf Green Seeds'!H2440) - 23 ),65536),4),"") -> BCA7 | I2440: =IFERROR(DEC2HEX(MOD((HEX2DEC('Leaf Green Seeds'!I2440) - 23 ),65536),4),"") -> BCA1 | J2440: =IFERROR(DEC2HEX(MOD((HEX2DEC('Leaf Green Seeds'!J2440) - 23 ),65536),4),"") | K2440: =IFERROR(DEC2HEX(MOD((HEX2DEC('Leaf Green Seeds'!K2440) - 23 ),65536),4),"") | ... Q2440: =IFERROR(DEC2HEX(MOD((HEX2DEC('Leaf Green Seeds'!Q2440) - 23 ),65536),4),"") -> BC9D

Sheet Held Blackout A Button
A1: Hold the A Button during the black screen right before the shooting star from the intro appears. You can let go of it as soon you can see the leaves on the title screen. | J1: Instead of pressing the A button on the title screen, press Start instead | P1: Instead of pressing the A button on the title screen, press L instead
A2: # | B2: Intro Time ms (GBA) | C2: Intro Time ms (NDS) | D2: MONO/LR | E2: MONO/L=A | F2: MONO/HELP | G2: STEREO/LR | H2: STEREO/L=A | I2: STEREO/HELP | J2: MONO/LR, Start | K2: MONO/L=A, Start | L2: MONO/HELP, Start | M2: STEREO/LR, Start | N2: STEREO/L=A, Start | O2: STEREO/HELP, Start | P2: MONO/L=A, L | Q2: STEREO/L=A, L
A3: 1 | B3: 33752 | C3: 34748 | D3: =IFERROR(DEC2HEX(MOD((HEX2DEC('Leaf Green Seeds'!D3) - 39 ),65536),4),"") -> A061 | E3: =IFERROR(DEC2HEX(MOD((HEX2DEC('Leaf Green Seeds'!E3) - 31 ),65536),4),"") -> A056 | F3: =IFERROR(DEC2HEX(MOD((HEX2DEC('Leaf Green Seeds'!F3) - 23 ),65536),4),"") -> A069 | G3: =IFERROR(DEC2HEX(MOD((HEX2DEC('Leaf Green Seeds'!G3) - 39 ),65536),4),"") -> A08C | H3: =IFERROR(DEC2HEX(MOD((HEX2DEC('Leaf Green Seeds'!H3) - 31 ),65536),4),"") -> A098 | I3: =IFERROR(DEC2HEX(MOD((HEX2DEC('Leaf Green Seeds'!I3) - 23 ),65536),4),"") -> A094 | J3: =IFERROR(DEC2HEX(MOD((HEX2DEC('Leaf Green Seeds'!J3) - 39 ),65536),4),"") -> A057 | K3: =IFERROR(DEC2HEX(MOD((HEX2DEC('Leaf Green Seeds'!K3) - 31 ),65536),4),"") -> A058 | L3: =IFERROR(DEC2HEX(MOD((HEX2DEC('Leaf Green Seeds'!L3) - 23 ),65536),4),"") -> A056 | M3: =IFERROR(DEC2HEX(MOD((HEX2DEC('Leaf Green Seeds'!M3) - 39 ),65536),4),"") -> A090 | N3: =IFERROR(DEC2HEX(MOD((HEX2DEC('Leaf Green Seeds'!N3) - 31 ),65536),4),"") -> A08E | O3: =IFERROR(DEC2HEX(MOD((HEX2DEC('Leaf Green Seeds'!O3) - 23 ),65536),4),"") -> A095 | P3: =IFERROR(DEC2HEX(MOD((HEX2DEC('Leaf Green Seeds'!P3) - 31 ),65536),4),"") -> A05F | Q3: =IFERROR(DEC2HEX(MOD((HEX2DEC('Leaf Green Seeds'!Q3) - 31 ),65536),4),"") -> A094
A4: 2 | B4: 33768 | C4: 34764 | D4: =IFERROR(DEC2HEX(MOD((HEX2DEC('Leaf Green Seeds'!D4) - 39 ),65536),4),"") -> ECA8 | E4: =IFERROR(DEC2HEX(MOD((HEX2DEC('Leaf Green Seeds'!E4) - 31 ),65536),4),"") -> ECA5 | F4: =IFERROR(DEC2HEX(MOD((HEX2DEC('Leaf Green Seeds'!F4) - 23 ),65536),4),"") -> ECAF | G4: =IFERROR(DEC2HEX(MOD((HEX2DEC('Leaf Green Seeds'!G4) - 39 ),65536),4),"") -> EC9E | H4: =IFERROR(DEC2HEX(MOD((HEX2DEC('Leaf Green Seeds'!H4) - 31 ),65536),4),"") -> EC9D | I4: =IFERROR(DEC2HEX(MOD((HEX2DEC('Leaf Green Seeds'!I4) - 23 ),65536),4),"") -> ECA6 | J4: =IFERROR(DEC2HEX(MOD((HEX2DEC('Leaf Green Seeds'!J4) - 39 ),65536),4),"") -> EC96 | K4: =IFERROR(DEC2HEX(MOD((HEX2DEC('Leaf Green Seeds'!K4) - 31 ),65536),4),"") -> EC95 | L4: =IFERROR(DEC2HEX(MOD((HEX2DEC('Leaf Green Seeds'!L4) - 23 ),65536),4),"") -> EC9E | M4: =IFERROR(DEC2HEX(MOD((HEX2DEC('Leaf Green Seeds'!M4) - 39 ),65536),4),"") -> EC9F | N4: =IFERROR(DEC2HEX(MOD((HEX2DEC('Leaf Green Seeds'!N4) - 31 ),65536),4),"") -> ECA0 | O4: =IFERROR(DEC2HEX(MOD((HEX2DEC('Leaf Green Seeds'!O4) - 23 ),65536),4),"") -> EC9E | P4: =IFERROR(DEC2HEX(MOD((HEX2DEC('Leaf Green Seeds'!P4) - 31 ),65536),4),"") -> EC9D | Q4: =IFERROR(DEC2HEX(MOD((HEX2DEC('Leaf Green Seeds'!Q4) - 31 ),65536),4),"") -> ECA3
A5: 3 | B5: 33784 | C5: 34780 | D5: =IFERROR(DEC2HEX(MOD((HEX2DEC('Leaf Green Seeds'!D5) - 39 ),65536),4),"") -> 368E | E5: =IFERROR(DEC2HEX(MOD((HEX2DEC('Leaf Green Seeds'!E5) - 31 ),65536),4),"") -> 3688 | F5: =IFERROR(DEC2HEX(MOD((HEX2DEC('Leaf Green Seeds'!F5) - 23 ),65536),4),"") -> 3691 | G5: =IFERROR(DEC2HEX(MOD((HEX2DEC('Leaf Green Seeds'!G5) - 39 ),65536),4),"") -> 36A7 | H5: =IFERROR(DEC2HEX(MOD((HEX2DEC('Leaf Green Seeds'!H5) - 31 ),65536),4),"") -> 36B0 | I5: =IFERROR(DEC2HEX(MOD((HEX2DEC('Leaf Green Seeds'!I5) - 23 ),65536),4),"") -> 36B9 | J5: =IFERROR(DEC2HEX(MOD((HEX2DEC('Leaf Green Seeds'!J5) - 39 ),65536),4),"") -> 3686 | K5: =IFERROR(DEC2HEX(MOD((HEX2DEC('Leaf Green Seeds'!K5) - 31 ),65536),4),"") -> 3685 | L5: =IFERROR(DEC2HEX(MOD((HEX2DEC('Leaf Green Seeds'!L5) - 23 ),65536),4),"") -> 3689 | M5: =IFERROR(DEC2HEX(MOD((HEX2DEC('Leaf Green Seeds'!M5) - 39 ),65536),4),"") -> 369F | N5: =IFERROR(DEC2HEX(MOD((HEX2DEC('Leaf Green Seeds'!N5) - 31 ),65536),4),"") -> 36A8 | O5: =IFERROR(DEC2HEX(MOD((HEX2DEC('Leaf Green Seeds'!O5) - 23 ),65536),4),"") -> 36A7 | P5: =IFERROR(DEC2HEX(MOD((HEX2DEC('Leaf Green Seeds'!P5) - 31 ),65536),4),"") -> 368A | Q5: =IFERROR(DEC2HEX(MOD((HEX2DEC('Leaf Green Seeds'!Q5) - 31 ),65536),4),"") -> 36A3
A6: 4 | B6: 33808 | C6: 34804 | D6: =IFERROR(DEC2HEX(MOD((HEX2DEC('Leaf Green Seeds'!D6) - 39 ),65536),4),"") -> 7F1C | E6: =IFERROR(DEC2HEX(MOD((HEX2DEC('Leaf Green Seeds'!E6) - 31 ),65536),4),"") -> 7F23 | F6: =IFERROR(DEC2HEX(MOD((HEX2DEC('Leaf Green Seeds'!F6) - 23 ),65536),4),"") -> 7F2D | G6: =IFERROR(DEC2HEX(MOD((HEX2DEC('Leaf Green Seeds'!G6) - 39 ),65536),4),"") -> 7F1C | H6: =IFERROR(DEC2HEX(MOD((HEX2DEC('Leaf Green Seeds'!H6) - 31 ),65536),4),"") -> 7F23 | I6: =IFERROR(DEC2HEX(MOD((HEX2DEC('Leaf Green Seeds'!I6) - 23 ),65536),4),"") -> 7F2D | J6: =IFERROR(DEC2HEX(MOD((HEX2DEC('Leaf Green Seeds'!J6) - 39 ),65536),4),"") -> 7F1D | K6: =IFERROR(DEC2HEX(MOD((HEX2DEC('Leaf Green Seeds'!K6) - 31 ),65536),4),"") -> 7F1B | L6: =IFERROR(DEC2HEX(MOD((HEX2DEC('Leaf Green Seeds'!L6) - 23 ),65536),4),"") -> 7F25 | M6: =IFERROR(DEC2HEX(MOD((HEX2DEC('Leaf Green Seeds'!M6) - 39 ),65536),4),"") -> 7F1D | N6: =IFERROR(DEC2HEX(MOD((HEX2DEC('Leaf Green Seeds'!N6) - 31 ),65536),4),"") -> 7F1B | O6: =IFERROR(DEC2HEX(MOD((HEX2DEC('Leaf Green Seeds'!O6) - 23 ),65536),4),"") -> 7F1C | P6: =IFERROR(DEC2HEX(MOD((HEX2DEC('Leaf Green Seeds'!P6) - 31 ),65536),4),"") -> 7F18 | Q6: =IFERROR(DEC2HEX(MOD((HEX2DEC('Leaf Green Seeds'!Q6) - 31 ),65536),4),"") -> 7F21
A7: 5 | B7: 33824 | C7: 34820 | D7: =IFERROR(DEC2HEX(MOD((HEX2DEC('Leaf Green Seeds'!D7) - 39 ),65536),4),"") -> C911 | E7: =IFERROR(DEC2HEX(MOD((HEX2DEC('Leaf Green Seeds'!E7) - 31 ),65536),4),"") -> C90D | F7: =IFERROR(DEC2HEX(MOD((HEX2DEC('Leaf Green Seeds'!F7) - 23 ),65536),4),"") -> C918 | G7: =IFERROR(DEC2HEX(MOD((HEX2DEC('Leaf Green Seeds'!G7) - 39 ),65536),4),"") -> C934 | H7: =IFERROR(DEC2HEX(MOD((HEX2DEC('Leaf Green Seeds'!H7) - 31 ),65536),4),"") -> C925 | I7: =IFERROR(DEC2HEX(MOD((HEX2DEC('Leaf Green Seeds'!I7) - 23 ),65536),4),"") -> C93A | J7: =IFERROR(DEC2HEX(MOD((HEX2DEC('Leaf Green Seeds'!J7) - 39 ),65536),4),"") -> C909 | K7: =IFERROR(DEC2HEX(MOD((HEX2DEC('Leaf Green Seeds'!K7) - 31 ),65536),4),"") -> C905 | L7: =IFERROR(DEC2HEX(MOD((HEX2DEC('Leaf Green Seeds'!L7) - 23 ),65536),4),"") -> C909 | M7: =IFERROR(DEC2HEX(MOD((HEX2DEC('Leaf Green Seeds'!M7) - 39 ),65536),4),"") -> C928 | N7: =IFERROR(DEC2HEX(MOD((HEX2DEC('Leaf Green Seeds'!N7) - 31 ),65536),4),"") -> C91D | O7: =IFERROR(DEC2HEX(MOD((HEX2DEC('Leaf Green Seeds'!O7) - 23 ),65536),4),"") -> C926 | P7: =IFERROR(DEC2HEX(MOD((HEX2DEC('Leaf Green Seeds'!P7) - 31 ),65536),4),"") -> C90A | Q7: =IFERROR(DEC2HEX(MOD((HEX2DEC('Leaf Green Seeds'!Q7) - 31 ),65536),4),"") -> C92C
A8: 6 | B8: 33840 | C8: 34836 | D8: =IFERROR(DEC2HEX(MOD((HEX2DEC('Leaf Green Seeds'!D8) - 39 ),65536),4),"") -> 1190 | E8: =IFERROR(DEC2HEX(MOD((HEX2DEC('Leaf Green Seeds'!E8) - 31 ),65536),4),"") -> 1196 | F8: =IFERROR(DEC2HEX(MOD((HEX2DEC('Leaf Green Seeds'!F8) - 23 ),65536),4),"") -> 1198 | G8: =IFERROR(DEC2HEX(MOD((HEX2DEC('Leaf Green Seeds'!G8) - 39 ),65536),4),"") -> 1190 | H8: =IFERROR(DEC2HEX(MOD((HEX2DEC('Leaf Green Seeds'!H8) - 31 ),65536),4),"") -> 118D | I8: =IFERROR(DEC2HEX(MOD((HEX2DEC('Leaf Green Seeds'!I8) - 23 ),65536),4),"") -> 1198 | J8: =IFERROR(DEC2HEX(MOD((HEX2DEC('Leaf Green Seeds'!J8) - 39 ),65536),4),"") -> 1193 | K8: =IFERROR(DEC2HEX(MOD((HEX2DEC('Leaf Green Seeds'!K8) - 31 ),65536),4),"") -> 1185 | L8: =IFERROR(DEC2HEX(MOD((HEX2DEC('Leaf Green Seeds'!L8) - 23 ),65536),4),"") -> 119B | M8: =IFERROR(DEC2HEX(MOD((HEX2DEC('Leaf Green Seeds'!M8) - 39 ),65536),4),"") -> 1187 | N8: =IFERROR(DEC2HEX(MOD((HEX2DEC('Leaf Green Seeds'!N8) - 31 ),65536),4),"") -> 118E | O8: =IFERROR(DEC2HEX(MOD((HEX2DEC('Leaf Green Seeds'!O8) - 23 ),65536),4),"") -> 118F | P8: =IFERROR(DEC2HEX(MOD((HEX2DEC('Leaf Green Seeds'!P8) - 31 ),65536),4),"") -> 118A | Q8: =IFERROR(DEC2HEX(MOD((HEX2DEC('Leaf Green Seeds'!Q8) - 31 ),65536),4),"") -> 1198
A9: 7 | B9: 33856 | C9: 34852 | D9: =IFERROR(DEC2HEX(MOD((HEX2DEC('Leaf Green Seeds'!D9) - 39 ),65536),4),"") -> 3FA5 | E9: =IFERROR(DEC2HEX(MOD((HEX2DEC('Leaf Green Seeds'!E9) - 31 ),65536),4),"") -> 3FA3 | F9: =IFERROR(DEC2HEX(MOD((HEX2DEC('Leaf Green Seeds'!F9) - 23 ),65536),4),"") -> 3FAD | G9: =IFERROR(DEC2HEX(MOD((HEX2DEC('Leaf Green Seeds'!G9) - 39 ),65536),4),"") -> 3FC3 | H9: =IFERROR(DEC2HEX(MOD((HEX2DEC('Leaf Green Seeds'!H9) - 31 ),65536),4),"") -> 3FC2 | I9: =IFERROR(DEC2HEX(MOD((HEX2DEC('Leaf Green Seeds'!I9) - 23 ),65536),4),"") -> 3FCB | J9: =IFERROR(DEC2HEX(MOD((HEX2DEC('Leaf Green Seeds'!J9) - 39 ),65536),4),"") -> 3F91 | K9: =IFERROR(DEC2HEX(MOD((HEX2DEC('Leaf Green Seeds'!K9) - 31 ),65536),4),"") -> 3F90 | L9: =IFERROR(DEC2HEX(MOD((HEX2DEC('Leaf Green Seeds'!L9) - 23 ),65536),4),"") -> 3FA4 | M9: =IFERROR(DEC2HEX(MOD((HEX2DEC('Leaf Green Seeds'!M9) - 39 ),65536),4),"") -> 3FB0 | N9: =IFERROR(DEC2HEX(MOD((HEX2DEC('Leaf Green Seeds'!N9) - 31 ),65536),4),"") -> 3FBA | O9: =IFERROR(DEC2HEX(MOD((HEX2DEC('Leaf Green Seeds'!O9) - 23 ),65536),4),"") -> 3FC2 | P9: =IFERROR(DEC2HEX(MOD((HEX2DEC('Leaf Green Seeds'!P9) - 31 ),65536),4),"") -> 3FA0 | Q9: =IFERROR(DEC2HEX(MOD((HEX2DEC('Leaf Green Seeds'!Q9) - 31 ),65536),4),"") -> 3FBE
A10: 8 | B10: 33872 | C10: 34868 | D10: =IFERROR(DEC2HEX(MOD((HEX2DEC('Leaf Green Seeds'!D10) - 39 ),65536),4),"") -> 96B7 | E10: =IFERROR(DEC2HEX(MOD((HEX2DEC('Leaf Green Seeds'!E10) - 31 ),65536),4),"") -> 96B6 | F10: =IFERROR(DEC2HEX(MOD((HEX2DEC('Leaf Green Seeds'!F10) - 23 ),65536),4),"") -> 96C7 | G10: =IFERROR(DEC2HEX(MOD((HEX2DEC('Leaf Green Seeds'!G10) - 39 ),65536),4),"") -> 96DD | H10: =IFERROR(DEC2HEX(MOD((HEX2DEC('Leaf Green Seeds'!H10) - 31 ),65536),4),"") -> 96DF | I10: =IFERROR(DEC2HEX(MOD((HEX2DEC('Leaf Green Seeds'!I10) - 23 ),65536),4),"") -> 96E5 | J10: =IFERROR(DEC2HEX(MOD((HEX2DEC('Leaf Green Seeds'!J10) - 39 ),65536),4),"") -> 96B7 | K10: =IFERROR(DEC2HEX(MOD((HEX2DEC('Leaf Green Seeds'!K10) - 31 ),65536),4),"") -> 96B8 | L10: =IFERROR(DEC2HEX(MOD((HEX2DEC('Leaf Green Seeds'!L10) - 23 ),65536),4),"") -> 96C2 | M10: =IFERROR(DEC2HEX(MOD((HEX2DEC('Leaf Green Seeds'!M10) - 39 ),65536),4),"") -> 96CD | N10: =IFERROR(DEC2HEX(MOD((HEX2DEC('Leaf Green Seeds'!N10) - 31 ),65536),4),"") -> 96D4 | O10: =IFERROR(DEC2HEX(MOD((HEX2DEC('Leaf Green Seeds'!O10) - 23 ),65536),4),"") -> 96E0 | P10: =IFERROR(DEC2HEX(MOD((HEX2DEC('Leaf Green Seeds'!P10) - 31 ),65536),4),"") -> 96BD | Q10: =IFERROR(DEC2HEX(MOD((HEX2DEC('Leaf Green Seeds'!Q10) - 31 ),65536),4),"") -> 96D9
A11: 9 | B11: 33888 | C11: 34884 | D11: =IFERROR(DEC2HEX(MOD((HEX2DEC('Leaf Green Seeds'!D11) - 39 ),65536),4),"") -> D4A2 | E11: =IFERROR(DEC2HEX(MOD((HEX2DEC('Leaf Green Seeds'!E11) - 31 ),65536),4),"") -> D4A1 | F11: =IFERROR(DEC2HEX(MOD((HEX2DEC('Leaf Green Seeds'!F11) - 23 ),65536),4),"") -> D4B3 | G11: =IFERROR(DEC2HEX(MOD((HEX2DEC('Leaf Green Seeds'!G11) - 39 ),65536),4),"") -> D4A2 | H11: =IFERROR(DEC2HEX(MOD((HEX2DEC('Leaf Green Seeds'!H11) - 31 ),65536),4),"") -> D4A1 | I11: =IFERROR(DEC2HEX(MOD((HEX2DEC('Leaf Green Seeds'!I11) - 23 ),65536),4),"") -> D4AA | J11: =IFERROR(DEC2HEX(MOD((HEX2DEC('Leaf Green Seeds'!J11) - 39 ),65536),4),"") -> D49A | K11: =IFERROR(DEC2HEX(MOD((HEX2DEC('Leaf Green Seeds'!K11) - 31 ),65536),4),"") -> D4A1 | L11: =IFERROR(DEC2HEX(MOD((HEX2DEC('Leaf Green Seeds'!L11) - 23 ),65536),4),"") -> D4A2 | M11: =IFERROR(DEC2HEX(MOD((HEX2DEC('Leaf Green Seeds'!M11) - 39 ),65536),4),"") -> D4A2 | N11: =IFERROR(DEC2HEX(MOD((HEX2DEC('Leaf Green Seeds'!N11) - 31 ),65536),4),"") -> D499 | O11: =IFERROR(DEC2HEX(MOD((HEX2DEC('Leaf Green Seeds'!O11) - 23 ),65536),4),"") -> D4A2 | P11: =IFERROR(DEC2HEX(MOD((HEX2DEC('Leaf Green Seeds'!P11) - 31 ),65536),4),"") -> D49E | Q11: =IFERROR(DEC2HEX(MOD((HEX2DEC('Leaf Green Seeds'!Q11) - 31 ),65536),4),"") -> D49E
A12: 10 | B12: 33904 | C12: 34900 | D12: =IFERROR(DEC2HEX(MOD((HEX2DEC('Leaf Green Seeds'!D12) - 39 ),65536),4),"") -> 1E6F | E12: =IFERROR(DEC2HEX(MOD((HEX2DEC('Leaf Green Seeds'!E12) - 31 ),65536),4),"") -> 1E6E | F12: =IFERROR(DEC2HEX(MOD((HEX2DEC('Leaf Green Seeds'!F12) - 23 ),65536),4),"") -> 1E81 | G12: =IFERROR(DEC2HEX(MOD((HEX2DEC('Leaf Green Seeds'!G12) - 39 ),65536),4),"") -> 1E8E | H12: =IFERROR(DEC2HEX(MOD((HEX2DEC('Leaf Green Seeds'!H12) - 31 ),65536),4),"") -> 1E8D | I12: =IFERROR(DEC2HEX(MOD((HEX2DEC('Leaf Green Seeds'!I12) - 23 ),65536),4),"") -> 1E9F | J12: =IFERROR(DEC2HEX(MOD((HEX2DEC('Leaf Green Seeds'!J12) - 39 ),65536),4),"") -> 1E67 | K12: =IFERROR(DEC2HEX(MOD((HEX2DEC('Leaf Green Seeds'!K12) - 31 ),65536),4),"") -> 1E66 | L12: =IFERROR(DEC2HEX(MOD((HEX2DEC('Leaf Green Seeds'!L12) - 23 ),65536),4),"") -> 1E79 | M12: =IFERROR(DEC2HEX(MOD((HEX2DEC('Leaf Green Seeds'!M12) - 39 ),65536),4),"") -> 1E8F | N12: =IFERROR(DEC2HEX(MOD((HEX2DEC('Leaf Green Seeds'!N12) - 31 ),65536),4),"") -> 1E85 | O12: =IFERROR(DEC2HEX(MOD((HEX2DEC('Leaf Green Seeds'!O12) - 23 ),65536),4),"") -> 1E97 | P12: =IFERROR(DEC2HEX(MOD((HEX2DEC('Leaf Green Seeds'!P12) - 31 ),65536),4),"") -> 1E75 | Q12: =IFERROR(DEC2HEX(MOD((HEX2DEC('Leaf Green Seeds'!Q12) - 31 ),65536),4),"") -> 1E8A
A13: 11 | B13: 33920 | C13: 34916 | D13: =IFERROR(DEC2HEX(MOD((HEX2DEC('Leaf Green Seeds'!D13) - 39 ),65536),4),"") -> 921C | E13: =IFERROR(DEC2HEX(MOD((HEX2DEC('Leaf Green Seeds'!E13) - 31 ),65536),4),"") -> 9213 | F13: =IFERROR(DEC2HEX(MOD((HEX2DEC('Leaf Green Seeds'!F13) - 23 ),65536),4),"") -> 9226 | G13: =IFERROR(DEC2HEX(MOD((HEX2DEC('Leaf Green Seeds'!G13) - 39 ),65536),4),"") -> 921C | H13: =IFERROR(DEC2HEX(MOD((HEX2DEC('Leaf Green Seeds'!H13) - 31 ),65536),4),"") -> 921B | I13: =IFERROR(DEC2HEX(MOD((HEX2DEC('Leaf Green Seeds'!I13) - 23 ),65536),4),"") -> 9224 | J13: =IFERROR(DEC2HEX(MOD((HEX2DEC('Leaf Green Seeds'!J13) - 39 ),65536),4),"") -> 920C | K13: =IFERROR(DEC2HEX(MOD((HEX2DEC('Leaf Green Seeds'!K13) - 31 ),65536),4),"") -> 9213 | L13: =IFERROR(DEC2HEX(MOD((HEX2DEC('Leaf Green Seeds'!L13) - 23 ),65536),4),"") -> 9214 | M13: =IFERROR(DEC2HEX(MOD((HEX2DEC('Leaf Green Seeds'!M13) - 39 ),65536),4),"") -> 9214 | N13: =IFERROR(DEC2HEX(MOD((HEX2DEC('Leaf Green Seeds'!N13) - 31 ),65536),4),"") -> 920B | O13: =IFERROR(DEC2HEX(MOD((HEX2DEC('Leaf Green Seeds'!O13) - 23 ),65536),4),"") -> 9214 | P13: =IFERROR(DEC2HEX(MOD((HEX2DEC('Leaf Green Seeds'!P13) - 31 ),65536),4),"") -> 9210 | Q13: =IFERROR(DEC2HEX(MOD((HEX2DEC('Leaf Green Seeds'!Q13) - 31 ),65536),4),"") -> 9210
