Workbook

Sheet Leaf Green Seeds
A1: Seeds for the Spanish, French, Italian and German Leaf Green versions based on the seeds farmed by po and 10Ben and converted by Mucks
A2: # | B2: Intro Time ms (GBA) | C2: Intro Time ms (NDS) | D2: MONO/LR | E2: MONO/L=A | F2: MONO/HELP | G2: STEREO/LR | H2: STEREO/L=A | I2: STEREO/HELP | J2: MONO/LR, Start | K2: MONO/L=A, Start | L2: MONO/HELP, Start | M2: STEREO/LR, Start | N2: STEREO/L=A, Start | O2: STEREO/HELP, Start
A3: 1 | B3: 33752 | C3: 34748 | D3: A080 | E3: A074 | F3: A080 | G3: A0AB | H3: A0B6 | I3: A0AB | J3: A076 | K3: A076 | L3: A06D | M3: A0AF | N3: A0AC | O3: A0AC
A4: 2 | B4: 33768 | C4: 34764 | D4: ECC7 | E4: ECC3 | F4: ECC6 | G4: ECBD | H4: ECBB | I4: ECBD | J4: ECB5 | K4: ECB3 | L4: ECB5 | M4: ECBE | N4: ECBE | O4: ECB5
A5: 3 | B5: 33784 | C5: 34780 | D5: 36AD | E5: 36A6 | F5: 36A8 | G5: 36C6 | H5: 36CE | I5: 36D0 | J5: 36A5 | K5: 36A3 | L5: 36A0 | M5: 36BE | N5: 36C6 | O5: 36BE
A6: 4 | B6: 33808 | C6: 34804 | D6: 7F3B | E6: 7F41 | F6: 7F44 | G6: 7F3B | H6: 7F41 | I6: 7F44 | J6: 7F3C | K6: 7F39 | L6: 7F3C | M6: 7F3C | N6: 7F39 | O6: 7F33
A7: 5 | B7: 33824 | C7: 34820 | D7: C930 | E7: C92B | F7: C92F | G7: C953 | H7: C943 | I7: C951 | J7: C928 | K7: C923 | L7: C920 | M7: C947 | N7: C93B | O7: C93D
A8: 6 | B8: 33840 | C8: 34836 | D8: 11AF | E8: 11B4 | F8: 11AF | G8: 11AF | H8: 11AB | I8: 11AF | J8: 11B2 | K8: 11A3 | L8: 11B2 | M8: 11A6 | N8: 11AC | O8: 11A6
A9: 7 | B9: 33856 | C9: 34852 | D9: 3FC4 | E9: 3FC1 | F9: 3FC4 | G9: 3FE2 | H9: 3FE0 | I9: 3FE2 | J9: 3FB0 | K9: 3FAE | L9: 3FBB | M9: 3FCF | N9: 3FD8 | O9: 3FD9
A10: 8 | B10: 33872 | C10: 34868 | D10: 96D6 | E10: 96D4 | F10: 96DE | G10: 96FC | H10: 96FD | I10: 96FC | J10: 96D6 | K10: 96D6 | L10: 96D9 | M10: 96EC | N10: 96F2 | O10: 96F7
A11: 9 | B11: 33888 | C11: 34884 | D11: D4C1 | E11: D4BF | F11: D4CA | G11: D4C1 | H11: D4BF | I11: D4C1 | J11: D4B9 | K11: D4BF | L11: D4B9 | M11: D4C1 | N11: D4B7 | O11: D4B9
A12: 10 | B12: 33904 | C12: 34900 | D12: 1E8E | E12: 1E8C | F12: 1E98 | G12: 1EAD | H12: 1EAB | I12: 1EB6 | J12: 1E86 | K12: 1E84 | L12: 1E90 | M12: 1EAE | N12: 1EA3 | O12: 1EAE
A13: 11 | B13: 33920 | C13: 34916 | D13: 923B | E13: 9231 | F13: 923D | G13: 923B | H13: 9239 | I13: 923B | J13: 922B | K13: 9231 | L13: 922B | M13: 9233 | N13: 9229 | O13: 922B
A14: 12 | B14: 33936 | C14: 34932 | D14: CF0C | E14: CF03 | F14: CF05 | G14: CF28 | H14: CF1A | I14: CF1C | J14: CF06 | K14: CEFB | L14: CF07 | M14: CF1F | N14: CF1A | O14: CF1C
... A2433: 2431 | B2433: 74520 | C2433: 75516 | D2433: E670 | E2433: E66E | F2433: E679 | G2433: E6B0 | H2433: E6AD | I2433: E6A5 | J2433: 0E8E | K2433: 7E1F | L2433: BC9B | M2433: 321A | N2433: 0EA9 | O2433: E6A7
A2434: 2432 | B2434: 74536 | C2434: 75532 | D2434: 322C | E2434: 3220 | F2434: 322D | G2434: 3222 | H2434: 3220 | I2434: 322C | J2434: 570D | K2434: BC8F | M2434: 7C2D | N2434: 5713 | O2434: 3224
A2435: 2433 | B2435: 74552 | C2435: 75548 | D2435: 7C19 | E2435: 7C0B | F2435: 7C16 | G2435: 7C37 | H2435: 7C33 | I2435: 7C33 | J2435: 7E17 | M2435: C48A | N2435: 7E3C | O2435: 7C2F
A2436: 2434 | B2436: 74568 | C2436: 75564 | D2436: C48A | E2436: C492 | F2436: C48A | G2436: C48A | H2436: C490 | I2436: C494 | J2436: BC91 | M2436: 0EAB | N2436: BCAE | O2436: C48A
A2437: 2435 | B2437: 74584 | C2437: 75580 | D2437: 0E99 | E2437: 0E8B | F2437: 0E8D | G2437: 0EB3 | H2437: 0EB1 | I2437: 0EB3 | M2437: 5718 | O2437: 0EAB
A2438: 2436 | B2438: 74600 | C2438: 75596 | D2438: 571F | E2438: 5713 | F2438: 5715 | G2438: 571D | H2438: 5713 | I2438: 5715 | M2438: 7E36 | O2438: 570D
A2439: 2437 | B2439: 74616 | C2439: 75612 | D2439: 7E1F | E2439: 7E28 | F2439: 7E29 | G2439: 7E3E | H2439: 7E44 | I2439: 7E46 | M2439: BCB7 | O2439: 7E36
A2440: 2438 | B2440: 74638 | C2440: 75632 | D2440: BCA2 | E2440: BCA1 | F2440: BCA2 | G2440: BCBF | H2440: BCBD | I2440: BCB8 | O2440: BCBA

Sheet Held Button
A1: Hold any of the Buttons B, Start, Select, Up, Left, Right, Down before you boot up the game. You can let go of it as soon you can see the leaves on the title screen.
A2: # | B2: Intro Time ms (GBA) | C2: Intro Time ms (NDS) | D2: MONO/LR | E2: MONO/L=A | F2: MONO/HELP | G2: STEREO/LR | H2: STEREO/L=A | I2: STEREO/HELP | J2: MONO/LR, Start | K2: MONO/L=A, Start | L2: MONO/HELP, Start | M2: STEREO/LR, Start | N2: STEREO/L=A, Start | O2: STEREO/HELP, Start
A3: 1 | B3: 33752 | C3: 34748 | D3: =IFERROR(DEC2HEX(MOD((HEX2DEC('Leaf Green Seeds'!D3) - 1 ),65536),4),"") -> A07F | E3: =IFERROR(DEC2HEX(MOD((HEX2DEC('Leaf Green Seeds'!E3) + 9 ),65536),4),"") -> A07D | F3: =IFERROR(DEC2HEX(MOD((HEX2DEC('Leaf Green Seeds'!F3) + 7 ),65536),4),"") -> A087 | G3: =IFERROR(DEC2HEX(MOD((HEX2DEC('Leaf Green Seeds'!G3) - 1 ),65536),4),"") -> A0AA | H3: =IFERROR(DEC2HEX(MOD((HEX2DEC('Leaf Green Seeds'!H3) + 9 ),65536),4),"") -> A0BF | I3: =IFERROR(DEC2HEX(MOD((HEX2DEC('Leaf Green Seeds'!I3) + 7 ),65536),4),"") -> A0B2 | J3: =IFERROR(DEC2HEX(MOD((HEX2DEC('Leaf Green Seeds'!J3) - 1 ),65536),4),"") -> A075 | K3: =IFERROR(DEC2HEX(MOD((HEX2DEC('Leaf Green Seeds'!K3) + 9 ),65536),4),"") -> A07F | L3: =IFERROR(DEC2HEX(MOD((HEX2DEC('Leaf Green Seeds'!L3) + 7 ),65536),4),"") -> A074 | M3: =IFERROR(DEC2HEX(MOD((HEX2DEC('Leaf Green Seeds'!M3) - 1 ),65536),4),"") -> A0AE | N3: =IFERROR(DEC2HEX(MOD((HEX2DEC('Leaf Green Seeds'!N3) + 9 ),65536),4),"") -> A0B5 | O3: =IFERROR(DEC2HEX(MOD((HEX2DEC('Leaf Green Seeds'!O3) + 7 ),65536),4),"") -> A0B3
A4: 2 | B4: 33768 | C4: 34764 | D4: =IFERROR(DEC2HEX(MOD((HEX2DEC('Leaf Green Seeds'!D4) - 1 ),65536),4),"") -> ECC6 | E4: =IFERROR(DEC2HEX(MOD((HEX2DEC('Leaf Green Seeds'!E4) + 9 ),65536),4),"") -> ECCC | F4: =IFERROR(DEC2HEX(MOD((HEX2DEC('Leaf Green Seeds'!F4) + 7 ),65536),4),"") -> ECCD | G4: =IFERROR(DEC2HEX(MOD((HEX2DEC('Leaf Green Seeds'!G4) - 1 ),65536),4),"") -> ECBC | H4: =IFERROR(DEC2HEX(MOD((HEX2DEC('Leaf Green Seeds'!H4) + 9 ),65536),4),"") -> ECC4 | I4: =IFERROR(DEC2HEX(MOD((HEX2DEC('Leaf Green Seeds'!I4) + 7 ),65536),4),"") -> ECC4 | J4: =IFERROR(DEC2HEX(MOD((HEX2DEC('Leaf Green Seeds'!J4) - 1 ),65536),4),"") -> ECB4 | K4: =IFERROR(DEC2HEX(MOD((HEX2DEC('Leaf Green Seeds'!K4) + 9 ),65536),4),"") -> ECBC | L4: =IFERROR(DEC2HEX(MOD((HEX2DEC('Leaf Green Seeds'!L4) + 7 ),65536),4),"") -> ECBC | M4: =IFERROR(DEC2HEX(MOD((HEX2DEC('Leaf Green Seeds'!M4) - 1 ),65536),4),"") -> ECBD | N4: =IFERROR(DEC2HEX(MOD((HEX2DEC('Leaf Green Seeds'!N4) + 9 ),65536),4),"") -> ECC7 | O4: =IFERROR(DEC2HEX(MOD((HEX2DEC('Leaf Green Seeds'!O4) + 7 ),65536),4),"") -> ECBC
A5: 3 | B5: 33784 | C5: 34780 | D5: =IFERROR(DEC2HEX(MOD((HEX2DEC('Leaf Green Seeds'!D5) - 1 ),65536),4),"") -> 36AC | E5: =IFERROR(DEC2HEX(MOD((HEX2DEC('Leaf Green Seeds'!E5) + 9 ),65536),4),"") -> 36AF | F5: =IFERROR(DEC2HEX(MOD((HEX2DEC('Leaf Green Seeds'!F5) + 7 ),65536),4),"") -> 36AF | G5: =IFERROR(DEC2HEX(MOD((HEX2DEC('Leaf Green Seeds'!G5) - 1 ),65536),4),"") -> 36C5 | H5: =IFERROR(DEC2HEX(MOD((HEX2DEC('Leaf Green Seeds'!H5) + 9 ),65536),4),"") -> 36D7 | I5: =IFERROR(DEC2HEX(MOD((HEX2DEC('Leaf Green Seeds'!I5) + 7 ),65536),4),"") -> 36D7 | J5: =IFERROR(DEC2HEX(MOD((HEX2DEC('Leaf Green Seeds'!J5) - 1 ),65536),4),"") -> 36A4 | K5: =IFERROR(DEC2HEX(MOD((HEX2DEC('Leaf Green Seeds'!K5) + 9 ),65536),4),"") -> 36AC | L5: =IFERROR(DEC2HEX(MOD((HEX2DEC('Leaf Green Seeds'!L5) + 7 ),65536),4),"") -> 36A7 | M5: =IFERROR(DEC2HEX(MOD((HEX2DEC('Leaf Green Seeds'!M5) - 1 ),65536),4),"") -> 36BD | N5: =IFERROR(DEC2HEX(MOD((HEX2DEC('Leaf Green Seeds'!N5) + 9 ),65536),4),"") -> 36CF | O5: =IFERROR(DEC2HEX(MOD((HEX2DEC('Leaf Green Seeds'!O5) + 7 ),65536),4),"") -> 36C5
A6: 4 | B6: 33808 | C6: 34804 | D6: =IFERROR(DEC2HEX(MOD((HEX2DEC('Leaf Green Seeds'!D6) - 1 ),65536),4),"") -> 7F3A | E6: =IFERROR(DEC2HEX(MOD((HEX2DEC('Leaf Green Seeds'!E6) + 9 ),65536),4),"") -> 7F4A | F6: =IFERROR(DEC2HEX(MOD((HEX2DEC('Leaf Green Seeds'!F6) + 7 ),65536),4),"") -> 7F4B | G6: =IFERROR(DEC2HEX(MOD((HEX2DEC('Leaf Green Seeds'!G6) - 1 ),65536),4),"") -> 7F3A | H6: =IFERROR(DEC2HEX(MOD((HEX2DEC('Leaf Green Seeds'!H6) + 9 ),65536),4),"") -> 7F4A | I6: =IFERROR(DEC2HEX(MOD((HEX2DEC('Leaf Green Seeds'!I6) + 7 ),65536),4),"") -> 7F4B | J6: =IFERROR(DEC2HEX(MOD((HEX2DEC('Leaf Green Seeds'!J6) - 1 ),65536),4),"") -> 7F3B | K6: =IFERROR(DEC2HEX(MOD((HEX2DEC('Leaf Green Seeds'!K6) + 9 ),65536),4),"") -> 7F42 | L6: =IFERROR(DEC2HEX(MOD((HEX2DEC('Leaf Green Seeds'!L6) + 7 ),65536),4),"") -> 7F43 | M6: =IFERROR(DEC2HEX(MOD((HEX2DEC('Leaf Green Seeds'!M6) - 1 ),65536),4),"") -> 7F3B | N6: =IFERROR(DEC2HEX(MOD((HEX2DEC('Leaf Green Seeds'!N6) + 9 ),65536),4),"") -> 7F42 | O6: =IFERROR(DEC2HEX(MOD((HEX2DEC('Leaf Green Seeds'!O6) + 7 ),65536),4),"") -> 7F3A
A7: 5 | B7: 33824 | C7: 34820 | D7: =IFERROR(DEC2HEX(MOD((HEX2DEC('Leaf Green Seeds'!D7) - 1 ),65536),4),"") -> C92F | E7: =IFERROR(DEC2HEX(MOD((HEX2DEC('Leaf Green Seeds'!E7) + 9 ),65536),4),"") -> C934 | F7: =IFERROR(DEC2HEX(MOD((HEX2DEC('Leaf Green Seeds'!F7) + 7 ),65536),4),"") -> C936 | G7: =IFERROR(DEC2HEX(MOD((HEX2DEC('Leaf Green Seeds'!G7) - 1 ),65536),4),"") -> C952 | H7: =IFERROR(DEC2HEX(MOD((HEX2DEC('Leaf Green Seeds'!H7) + 9 ),65536),4),"") -> C94C | I7: =IFERROR(DEC2HEX(MOD((HEX2DEC('Leaf Green Seeds'!I7) + 7 ),65536),4),"") -> C958 | J7: =IFERROR(DEC2HEX(MOD((HEX2DEC('Leaf Green Seeds'!J7) - 1 ),65536),4),"") -> C927 | K7: =IFERROR(DEC2HEX(MOD((HEX2DEC('Leaf Green Seeds'!K7) + 9 ),65536),4),"") -> C92C | L7: =IFERROR(DEC2HEX(MOD((HEX2DEC('Leaf Green Seeds'!L7) + 7 ),65536),4),"") -> C927 | M7: =IFERROR(DEC2HEX(MOD((HEX2DEC('Leaf Green Seeds'!M7) - 1 ),65536),4),"") -> C946 | N7: =IFERROR(DEC2HEX(MOD((HEX2DEC('Leaf Green Seeds'!N7) + 9 ),65536),4),"") -> C944 | O7: =IFERROR(DEC2HEX(MOD((HEX2DEC('Leaf Green Seeds'!O7) + 7 ),65536),4),"") -> C944
A8: 6 | B8: 33840 | C8: 34836 | D8: =IFERROR(DEC2HEX(MOD((HEX2DEC('Leaf Green Seeds'!D8) - 1 ),65536),4),"") -> 11AE | E8: =IFERROR(DEC2HEX(MOD((HEX2DEC('Leaf Green Seeds'!E8) + 9 ),65536),4),"") -> 11BD | F8: =IFERROR(DEC2HEX(MOD((HEX2DEC('Leaf Green Seeds'!F8) + 7 ),65536),4),"") -> 11B6 | G8: =IFERROR(DEC2HEX(MOD((HEX2DEC('Leaf Green Seeds'!G8) - 1 ),65536),4),"") -> 11AE | H8: =IFERROR(DEC2HEX(MOD((HEX2DEC('Leaf Green Seeds'!H8) + 9 ),65536),4),"") -> 11B4 | I8: =IFERROR(DEC2HEX(MOD((HEX2DEC('Leaf Green Seeds'!I8) + 7 ),65536),4),"") -> 11B6 | J8: =IFERROR(DEC2HEX(MOD((HEX2DEC('Leaf Green Seeds'!J8) - 1 ),65536),4),"") -> 11B1 | K8: =IFERROR(DEC2HEX(MOD((HEX2DEC('Leaf Green Seeds'!K8) + 9 ),65536),4),"") -> 11AC | L8: =IFERROR(DEC2HEX(MOD((HEX2DEC('Leaf Green Seeds'!L8) + 7 ),65536),4),"") -> 11B9 | M8: =IFERROR(DEC2HEX(MOD((HEX2DEC('Leaf Green Seeds'!M8) - 1 ),65536),4),"") -> 11A5 | N8: =IFERROR(DEC2HEX(MOD((HEX2DEC('Leaf Green Seeds'!N8) + 9 ),65536),4),"") -> 11B5 | O8: =IFERROR(DEC2HEX(MOD((HEX2DEC('Leaf Green Seeds'!O8) + 7 ),65536),4),"") -> 11AD
A9: 7 | B9: 33856 | C9: 34852 | D9: =IFERROR(DEC2HEX(MOD((HEX2DEC('Leaf Green Seeds'!D9) - 1 ),65536),4),"") -> 3FC3 | E9: =IFERROR(DEC2HEX(MOD((HEX2DEC('Leaf Green Seeds'!E9) + 9 ),65536),4),"") -> 3FCA | F9: =IFERROR(DEC2HEX(MOD((HEX2DEC('Leaf Green Seeds'!F9) + 7 ),65536),4),"") -> 3FCB | G9: =IFERROR(DEC2HEX(MOD((HEX2DEC('Leaf Green Seeds'!G9) - 1 ),65536),4),"") -> 3FE1 | H9: =IFERROR(DEC2HEX(MOD((HEX2DEC('Leaf Green Seeds'!H9) + 9 ),65536),4),"") -> 3FE9 | I9: =IFERROR(DEC2HEX(MOD((HEX2DEC('Leaf Green Seeds'!I9) + 7 ),65536),4),"") -> 3FE9 | J9: =IFERROR(DEC2HEX(MOD((HEX2DEC('Leaf Green Seeds'!J9) - 1 ),65536),4),"") -> 3FAF | K9: =IFERROR(DEC2HEX(MOD((HEX2DEC('Leaf Green Seeds'!K9) + 9 ),65536),4),"") -> 3FB7 | L9: =IFERROR(DEC2HEX(MOD((HEX2DEC('Leaf Green Seeds'!L9) + 7 ),65536),4),"") -> 3FC2 | M9: =IFERROR(DEC2HEX(MOD((HEX2DEC('Leaf Green Seeds'!M9) - 1 ),65536),4),"") -> 3FCE | N9: =IFERROR(DEC2HEX(MOD((HEX2DEC('Leaf Green Seeds'!N9) + 9 ),65536),4),"") -> 3FE1 | O9: =IFERROR(DEC2HEX(MOD((HEX2DEC('Leaf Green Seeds'!O9) + 7 ),65536),4),"") -> 3FE0
A10: 8 | B10: 33872 | C10: 34868 | D10: =IFERROR(DEC2HEX(MOD((HEX2DEC('Leaf Green Seeds'!D10) - 1 ),65536),4),"") -> 96D5 | E10: =IFERROR(DEC2HEX(MOD((HEX2DEC('Leaf Green Seeds'!E10) + 9 ),65536),4),"") -> 96DD | F10: =IFERROR(DEC2HEX(MOD((HEX2DEC('Leaf Green Seeds'!F10) + 7 ),65536),4),"") -> 96E5 | G10: =IFERROR(DEC2HEX(MOD((HEX2DEC('Leaf Green Seeds'!G10) - 1 ),65536),4),"") -> 96FB | H10: =IFERROR(DEC2HEX(MOD((HEX2DEC('Leaf Green Seeds'!H10) + 9 ),65536),4),"") -> 9706 | I10: =IFERROR(DEC2HEX(MOD((HEX2DEC('Leaf Green Seeds'!I10) + 7 ),65536),4),"") -> 9703 | J10: =IFERROR(DEC2HEX(MOD((HEX2DEC('Leaf Green Seeds'!J10) - 1 ),65536),4),"") -> 96D5 | K10: =IFERROR(DEC2HEX(MOD((HEX2DEC('Leaf Green Seeds'!K10) + 9 ),65536),4),"") -> 96DF | L10: =IFERROR(DEC2HEX(MOD((HEX2DEC('Leaf Green Seeds'!L10) + 7 ),65536),4),"") -> 96E0 | M10: =IFERROR(DEC2HEX(MOD((HEX2DEC('Leaf Green Seeds'!M10) - 1 ),65536),4),"") -> 96EB | N10: =IFERROR(DEC2HEX(MOD((HEX2DEC('Leaf Green Seeds'!N10) + 9 ),65536),4),"") -> 96FB | O10: =IFERROR(DEC2HEX(MOD((HEX2DEC('Leaf Green Seeds'!O10) + 7 ),65536),4),"") -> 96FE
A11: 9 | B11: 33888 | C11: 34884 | D11: =IFERROR(DEC2HEX(MOD((HEX2DEC('Leaf Green Seeds'!D11) - 1 ),65536),4),"") -> D4C0 | E11: =IFERROR(DEC2HEX(MOD((HEX2DEC('Leaf Green Seeds'!E11) + 9 ),65536),4),"") -> D4C8 | F11: =IFERROR(DEC2HEX(MOD((HEX2DEC('Leaf Green Seeds'!F11) + 7 ),65536),4),"") -> D4D1 | G11: =IFERROR(DEC2HEX(MOD((HEX2DEC('Leaf Green Seeds'!G11) - 1 ),65536),4),"") -> D4C0 | H11: =IFERROR(DEC2HEX(MOD((HEX2DEC('Leaf Green Seeds'!H11) + 9 ),65536),4),"") -> D4C8 | I11: =IFERROR(DEC2HEX(MOD((HEX2DEC('Leaf Green Seeds'!I11) + 7 ),65536),4),"") -> D4C8 | J11: =IFERROR(DEC2HEX(MOD((HEX2DEC('Leaf Green Seeds'!J11) - 1 ),65536),4),"") -> D4B8 | K11: =IFERROR(DEC2HEX(MOD((HEX2DEC('Leaf Green Seeds'!K11) + 9 ),65536),4),"") -> D4C8 | L11: =IFERROR(DEC2HEX(MOD((HEX2DEC('Leaf Green Seeds'!L11) + 7 ),65536),4),"") -> D4C0 | M11: =IFERROR(DEC2HEX(MOD((HEX2DEC('Leaf Green Seeds'!M11) - 1 ),65536),4),"") -> D4C0 | N11: =IFERROR(DEC2HEX(MOD((HEX2DEC('Leaf Green Seeds'!N11) + 9 ),65536),4),"") -> D4C0 | O11: =IFERROR(DEC2HEX(MOD((HEX2DEC('Leaf Green Seeds'!O11) + 7 ),65536),4),"") -> D4C0
A12: 10 | B12: 33904 | C12: 34900 | D12: =IFERROR(DEC2HEX(MOD((HEX2DEC('Leaf Green Seeds'!D12) - 1 ),65536),4),"") -> 1E8D | E12: =IFERROR(DEC2HEX(MOD((HEX2DEC('Leaf Green Seeds'!E12) + 9 ),65536),4),"") -> 1E95 | F12: =IFERROR(DEC2HEX(MOD((HEX2DEC('Leaf Green Seeds'!F12) + 7 ),65536),4),"") -> 1E9F | G12: =IFERROR(DEC2HEX(MOD((HEX2DEC('Leaf Green Seeds'!G12) - 1 ),65536),4),"") -> 1EAC | H12: =IFERROR(DEC2HEX(MOD((HEX2DEC('Leaf Green Seeds'!H12) + 9 ),65536),4),"") -> 1EB4 | I12: =IFERROR(DEC2HEX(MOD((HEX2DEC('Leaf Green Seeds'!I12) + 7 ),65536),4),"") -> 1EBD | J12: =IFERROR(DEC2HEX(MOD((HEX2DEC('Leaf Green Seeds'!J12) - 1 ),65536),4),"") -> 1E85 | K12: =IFERROR(DEC2HEX(MOD((HEX2DEC('Leaf Green Seeds'!K12) + 9 ),65536),4),"") -> 1E8D | L12: =IFERROR(DEC2HEX(MOD((HEX2DEC('Leaf Green Seeds'!L12) + 7 ),65536),4),"") -> 1E97 | M12: =IFERROR(DEC2HEX(MOD((HEX2DEC('Leaf Green Seeds'!M12) - 1 ),65536),4),"") -> 1EAD | N12: =IFERROR(DEC2HEX(MOD((HEX2DEC('Leaf Green Seeds'!N12) + 9 ),65536),4),"") -> 1EAC | O12: =IFERROR(DEC2HEX(MOD((HEX2DEC('Leaf Green Seeds'!O12) + 7 ),65536),4),"") -> 1EB5
A13: 11 | B13: 33920 | C13: 34916 | D13: =IFERROR(DEC2HEX(MOD((HEX2DEC('Leaf Green Seeds'!D13) - 1 ),65536),4),"") -> 923A | E13: =IFERROR(DEC2HEX(MOD((HEX2DEC('Leaf Green Seeds'!E13) + 9 ),65536),4),"") -> 923A | F13: =IFERROR(DEC2HEX(MOD((HEX2DEC('Leaf Green Seeds'!F13) + 7 ),65536),4),"") -> 9244 | G13: =IFERROR(DEC2HEX(MOD((HEX2DEC('Leaf Green Seeds'!G13) - 1 ),65536),4),"") -> 923A | H13: =IFERROR(DEC2HEX(MOD((HEX2DEC('Leaf Green Seeds'!H13) + 9 ),65536),4),"") -> 9242 | I13: =IFERROR(DEC2HEX(MOD((HEX2DEC('Leaf Green Seeds'!I13) + 7 ),65536),4),"") -> 9242 | J13: =IFERROR(DEC2HEX(MOD((HEX2DEC('Leaf Green Seeds'!J13) - 1 ),65536),4),"") -> 922A | K13: =IFERROR(DEC2HEX(MOD((HEX2DEC('Leaf Green Seeds'!K13) + 9 ),65536),4),"") -> 923A | L13: =IFERROR(DEC2HEX(MOD((HEX2DEC('Leaf Green Seeds'!L13) + 7 ),65536),4),"") -> 9232 | M13: =IFERROR(DEC2HEX(MOD((HEX2DEC('Leaf Green Seeds'!M13) - 1 ),65536),4),"") -> 9232 | N13: =IFERROR(DEC2HEX(MOD((HEX2DEC('Leaf Green Seeds'!N13) + 9 ),65536),4),"") -> 9232 | O13: =IFERROR(DEC2HEX(MOD((HEX2DEC('Leaf Green Seeds'!O13) + 7 ),65536),4),"") -> 9232
A14: 12 | B14: 33936 | C14: 34932 | D14: =IFERROR(DEC2HEX(MOD((HEX2DEC('Leaf Green Seeds'!D14) - 1 ),65536),4),"") -> CF0B | E14: =IFERROR(DEC2HEX(MOD((HEX2DEC('Leaf Green Seeds'!E14) + 9 ),65536),4),"") -> CF0C | F14: =IFERROR(DEC2HEX(MOD((HEX2DEC('Leaf Green Seeds'!F14) + 7 ),65536),4),"") -> CF0C | G14: =IFERROR(DEC2HEX(MOD((HEX2DEC('Leaf Green Seeds'!G14) - 1 ),65536),4),"") -> CF27 | H14: =IFERROR(DEC2HEX(MOD((HEX2DEC('Leaf Green Seeds'!H14) + 9 ),65536),4),"") -> CF23 | I14: =IFERROR(DEC2HEX(MOD((HEX2DEC('Leaf Green Seeds'!I14) + 7 ),65536),4),"") -> CF23 | J14: =IFERROR(DEC2HEX(MOD((HEX2DEC('Leaf Green Seeds'!J14) - 1 ),65536),4),"") -> CF05 | K14: =IFERROR(DEC2HEX(MOD((HEX2DEC('Leaf Green Seeds'!K14) + 9 ),65536),4),"") -> CF04 | L14: =IFERROR(DEC2HEX(MOD((HEX2DEC('Leaf Green Seeds'!L14) + 7 ),65536),4),"") -> CF0E | M14: =IFERROR(DEC2HEX(MOD((HEX2DEC('Leaf Green Seeds'!M14) - 1 ),65536),4),"") -> CF1E | N14: =IFERROR(DEC2HEX(MOD((HEX2DEC('Leaf Green Seeds'!N14) + 9 ),65536),4),"") -> CF23 | O14: =IFERROR(DEC2HEX(MOD((HEX2DEC('Leaf Green Seeds'!O14) + 7 ),65536),4),"") -> CF23
... A2440: 2438 | B2440: 74638 | C2440: 75632 | D2440: =IFERROR(DEC2HEX(MOD((HEX2DEC('Leaf Green Seeds'!D2440) - 1 ),65536),4),"") -> BCA1 | E2440: =IFERROR(DEC2HEX(MOD((HEX2DEC('Leaf Green Seeds'!E2440) + 9 ),65536),4),"") -> BCAA | F2440: =IFERROR(DEC2HEX(MOD((HEX2DEC('Leaf Green Seeds'!F2440) + 7 ),65536),4),"") -> BCA9 | G2440: =IFERROR(DEC2HEX(MOD((HEX2DEC('Leaf Green Seeds'!G2440) - 1 ),65536),4),"") -> BCBE | H2440: =IFERROR(DEC2HEX(MOD((HEX2DEC('Leaf Green Seeds'!H2440) + 9 ),65536),4),"") -> BCC6 | I2440: =IFERROR(DEC2HEX(MOD((HEX2DEC('Leaf Green Seeds'!I2440) + 7 ),65536),4),"") -> BCBF | J2440: =IFERROR(DEC2HEX(MOD((HEX2DEC('Leaf Green Seeds'!J2440) - 1 ),65536),4),"") | K2440: =IFERROR(DEC2HEX(MOD((HEX2DEC('Leaf Green Seeds'!K2440) + 9 ),65536),4),"") | L2440: =IFERROR(DEC2HEX(MOD((HEX2DEC('Leaf Green Seeds'!L2440) + 7 ),65536),4),"") | M2440: =IFERROR(DEC2HEX(MOD((HEX2DEC('Leaf Green Seeds'!M2440) - 1 ),65536),4),"") | N2440: =IFERROR(DEC2HEX(MOD((HEX2DEC('Leaf Green Seeds'!N2440) + 9 ),65536),4),"") | O2440: =IFERROR(DEC2HEX(MOD((HEX2DEC('Leaf Green Seeds'!O2440) + 7 ),65536),4),"") -> BCC1

Sheet Held Button (A)
A1: Hold the A Button before you boot up the game. Let go of it as soon you can see the leaves on the Venusaur title screen.
A2: # | B2: Intro Time ms (GBA) | C2: Intro Time ms (NDS) | D2: MONO/LR | E2: MONO/L=A | F2: MONO/HELP | G2: STEREO/LR | H2: STEREO/L=A | I2: STEREO/HELP | J2: MONO/LR, Start | K2: MONO/L=A, Start | L2: MONO/HELP, Start | M2: STEREO/LR, Start | N2: STEREO/L=A, Start | O2: STEREO/HELP, Start
A3: 1 | B3: 33752 | C3: 34748 | D3: =IFERROR(DEC2HEX(MOD((HEX2DEC('Leaf Green Seeds'!D3) - 11 ),65536),4),"") -> A075 | E3: =IFERROR(DEC2HEX(MOD((HEX2DEC('Leaf Green Seeds'!E3) - 9 ),65536),4),"") -> A06B | F3: =IFERROR(DEC2HEX(MOD((HEX2DEC('Leaf Green Seeds'!F3) + 3 ),65536),4),"") -> A083 | G3: =IFERROR(DEC2HEX(MOD((HEX2DEC('Leaf Green Seeds'!G3) - 11 ),65536),4),"") -> A0A0 | H3: =IFERROR(DEC2HEX(MOD((HEX2DEC('Leaf Green Seeds'!H3) - 9 ),65536),4),"") -> A0AD | I3: =IFERROR(DEC2HEX(MOD((HEX2DEC('Leaf Green Seeds'!I3) + 3 ),65536),4),"") -> A0AE | J3: =IFERROR(DEC2HEX(MOD((HEX2DEC('Leaf Green Seeds'!J3) - 11 ),65536),4),"") -> A06B | K3: =IFERROR(DEC2HEX(MOD((HEX2DEC('Leaf Green Seeds'!K3) - 9 ),65536),4),"") -> A06D | L3: =IFERROR(DEC2HEX(MOD((HEX2DEC('Leaf Green Seeds'!L3) + 3 ),65536),4),"") -> A070 | M3: =IFERROR(DEC2HEX(MOD((HEX2DEC('Leaf Green Seeds'!M3) - 11 ),65536),4),"") -> A0A4 | N3: =IFERROR(DEC2HEX(MOD((HEX2DEC('Leaf Green Seeds'!N3) - 9 ),65536),4),"") -> A0A3 | O3: =IFERROR(DEC2HEX(MOD((HEX2DEC('Leaf Green Seeds'!O3) + 3 ),65536),4),"") -> A0AF
A4: 2 | B4: 33768 | C4: 34764 | D4: =IFERROR(DEC2HEX(MOD((HEX2DEC('Leaf Green Seeds'!D4) - 11 ),65536),4),"") -> ECBC | E4: =IFERROR(DEC2HEX(MOD((HEX2DEC('Leaf Green Seeds'!E4) - 9 ),65536),4),"") -> ECBA | F4: =IFERROR(DEC2HEX(MOD((HEX2DEC('Leaf Green Seeds'!F4) + 3 ),65536),4),"") -> ECC9 | G4: =IFERROR(DEC2HEX(MOD((HEX2DEC('Leaf Green Seeds'!G4) - 11 ),65536),4),"") -> ECB2 | H4: =IFERROR(DEC2HEX(MOD((HEX2DEC('Leaf Green Seeds'!H4) - 9 ),65536),4),"") -> ECB2 | I4: =IFERROR(DEC2HEX(MOD((HEX2DEC('Leaf Green Seeds'!I4) + 3 ),65536),4),"") -> ECC0 | J4: =IFERROR(DEC2HEX(MOD((HEX2DEC('Leaf Green Seeds'!J4) - 11 ),65536),4),"") -> ECAA | K4: =IFERROR(DEC2HEX(MOD((HEX2DEC('Leaf Green Seeds'!K4) - 9 ),65536),4),"") -> ECAA | L4: =IFERROR(DEC2HEX(MOD((HEX2DEC('Leaf Green Seeds'!L4) + 3 ),65536),4),"") -> ECB8 | M4: =IFERROR(DEC2HEX(MOD((HEX2DEC('Leaf Green Seeds'!M4) - 11 ),65536),4),"") -> ECB3 | N4: =IFERROR(DEC2HEX(MOD((HEX2DEC('Leaf Green Seeds'!N4) - 9 ),65536),4),"") -> ECB5 | O4: =IFERROR(DEC2HEX(MOD((HEX2DEC('Leaf Green Seeds'!O4) + 3 ),65536),4),"") -> ECB8
A5: 3 | B5: 33784 | C5: 34780 | D5: =IFERROR(DEC2HEX(MOD((HEX2DEC('Leaf Green Seeds'!D5) - 11 ),65536),4),"") -> 36A2 | E5: =IFERROR(DEC2HEX(MOD((HEX2DEC('Leaf Green Seeds'!E5) - 9 ),65536),4),"") -> 369D | F5: =IFERROR(DEC2HEX(MOD((HEX2DEC('Leaf Green Seeds'!F5) + 3 ),65536),4),"") -> 36AB | G5: =IFERROR(DEC2HEX(MOD((HEX2DEC('Leaf Green Seeds'!G5) - 11 ),65536),4),"") -> 36BB | H5: =IFERROR(DEC2HEX(MOD((HEX2DEC('Leaf Green Seeds'!H5) - 9 ),65536),4),"") -> 36C5 | I5: =IFERROR(DEC2HEX(MOD((HEX2DEC('Leaf Green Seeds'!I5) + 3 ),65536),4),"") -> 36D3 | J5: =IFERROR(DEC2HEX(MOD((HEX2DEC('Leaf Green Seeds'!J5) - 11 ),65536),4),"") -> 369A | K5: =IFERROR(DEC2HEX(MOD((HEX2DEC('Leaf Green Seeds'!K5) - 9 ),65536),4),"") -> 369A | L5: =IFERROR(DEC2HEX(MOD((HEX2DEC('Leaf Green Seeds'!L5) + 3 ),65536),4),"") -> 36A3 | M5: =IFERROR(DEC2HEX(MOD((HEX2DEC('Leaf Green Seeds'!M5) - 11 ),65536),4),"") -> 36B3 | N5: =IFERROR(DEC2HEX(MOD((HEX2DEC('Leaf Green Seeds'!N5) - 9 ),65536),4),"") -> 36BD | O5: =IFERROR(DEC2HEX(MOD((HEX2DEC('Leaf Green Seeds'!O5) + 3 ),65536),4),"") -> 36C1
A6: 4 | B6: 33808 | C6: 34804 | D6: =IFERROR(DEC2HEX(MOD((HEX2DEC('Leaf Green Seeds'!D6) - 11 ),65536),4),"") -> 7F30 | E6: =IFERROR(DEC2HEX(MOD((HEX2DEC('Leaf Green Seeds'!E6) - 9 ),65536),4),"") -> 7F38 | F6: =IFERROR(DEC2HEX(MOD((HEX2DEC('Leaf Green Seeds'!F6) + 3 ),65536),4),"") -> 7F47 | G6: =IFERROR(DEC2HEX(MOD((HEX2DEC('Leaf Green Seeds'!G6) - 11 ),65536),4),"") -> 7F30 | H6: =IFERROR(DEC2HEX(MOD((HEX2DEC('Leaf Green Seeds'!H6) - 9 ),65536),4),"") -> 7F38 | I6: =IFERROR(DEC2HEX(MOD((HEX2DEC('Leaf Green Seeds'!I6) + 3 ),65536),4),"") -> 7F47 | J6: =IFERROR(DEC2HEX(MOD((HEX2DEC('Leaf Green Seeds'!J6) - 11 ),65536),4),"") -> 7F31 | K6: =IFERROR(DEC2HEX(MOD((HEX2DEC('Leaf Green Seeds'!K6) - 9 ),65536),4),"") -> 7F30 | L6: =IFERROR(DEC2HEX(MOD((HEX2DEC('Leaf Green Seeds'!L6) + 3 ),65536),4),"") -> 7F3F | M6: =IFERROR(DEC2HEX(MOD((HEX2DEC('Leaf Green Seeds'!M6) - 11 ),65536),4),"") -> 7F31 | N6: =IFERROR(DEC2HEX(MOD((HEX2DEC('Leaf Green Seeds'!N6) - 9 ),65536),4),"") -> 7F30 | O6: =IFERROR(DEC2HEX(MOD((HEX2DEC('Leaf Green Seeds'!O6) + 3 ),65536),4),"") -> 7F36
A7: 5 | B7: 33824 | C7: 34820 | D7: =IFERROR(DEC2HEX(MOD((HEX2DEC('Leaf Green Seeds'!D7) - 11 ),65536),4),"") -> C925 | E7: =IFERROR(DEC2HEX(MOD((HEX2DEC('Leaf Green Seeds'!E7) - 9 ),65536),4),"") -> C922 | F7: =IFERROR(DEC2HEX(MOD((HEX2DEC('Leaf Green Seeds'!F7) + 3 ),65536),4),"") -> C932 | G7: =IFERROR(DEC2HEX(MOD((HEX2DEC('Leaf Green Seeds'!G7) - 11 ),65536),4),"") -> C948 | H7: =IFERROR(DEC2HEX(MOD((HEX2DEC('Leaf Green Seeds'!H7) - 9 ),65536),4),"") -> C93A | I7: =IFERROR(DEC2HEX(MOD((HEX2DEC('Leaf Green Seeds'!I7) + 3 ),65536),4),"") -> C954 | J7: =IFERROR(DEC2HEX(MOD((HEX2DEC('Leaf Green Seeds'!J7) - 11 ),65536),4),"") -> C91D | K7: =IFERROR(DEC2HEX(MOD((HEX2DEC('Leaf Green Seeds'!K7) - 9 ),65536),4),"") -> C91A | L7: =IFERROR(DEC2HEX(MOD((HEX2DEC('Leaf Green Seeds'!L7) + 3 ),65536),4),"") -> C923 | M7: =IFERROR(DEC2HEX(MOD((HEX2DEC('Leaf Green Seeds'!M7) - 11 ),65536),4),"") -> C93C | N7: =IFERROR(DEC2HEX(MOD((HEX2DEC('Leaf Green Seeds'!N7) - 9 ),65536),4),"") -> C932 | O7: =IFERROR(DEC2HEX(MOD((HEX2DEC('Leaf Green Seeds'!O7) + 3 ),65536),4),"") -> C940
A8: 6 | B8: 33840 | C8: 34836 | D8: =IFERROR(DEC2HEX(MOD((HEX2DEC('Leaf Green Seeds'!D8) - 11 ),65536),4),"") -> 11A4 | E8: =IFERROR(DEC2HEX(MOD((HEX2DEC('Leaf Green Seeds'!E8) - 9 ),65536),4),"") -> 11AB | F8: =IFERROR(DEC2HEX(MOD((HEX2DEC('Leaf Green Seeds'!F8) + 3 ),65536),4),"") -> 11B2 | G8: =IFERROR(DEC2HEX(MOD((HEX2DEC('Leaf Green Seeds'!G8) - 11 ),65536),4),"") -> 11A4 | H8: =IFERROR(DEC2HEX(MOD((HEX2DEC('Leaf Green Seeds'!H8) - 9 ),65536),4),"") -> 11A2 | I8: =IFERROR(DEC2HEX(MOD((HEX2DEC('Leaf Green Seeds'!I8) + 3 ),65536),4),"") -> 11B2 | J8: =IFERROR(DEC2HEX(MOD((HEX2DEC('Leaf Green Seeds'!J8) - 11 ),65536),4),"") -> 11A7 | K8: =IFERROR(DEC2HEX(MOD((HEX2DEC('Leaf Green Seeds'!K8) - 9 ),65536),4),"") -> 119A | L8: =IFERROR(DEC2HEX(MOD((HEX2DEC('Leaf Green Seeds'!L8) + 3 ),65536),4),"") -> 11B5 | M8: =IFERROR(DEC2HEX(MOD((HEX2DEC('Leaf Green Seeds'!M8) - 11 ),65536),4),"") -> 119B | N8: =IFERROR(DEC2HEX(MOD((HEX2DEC('Leaf Green Seeds'!N8) - 9 ),65536),4),"") -> 11A3 | O8: =IFERROR(DEC2HEX(MOD((HEX2DEC('Leaf Green Seeds'!O8) + 3 ),65536),4),"") -> 11A9
A9: 7 | B9: 33856 | C9: 34852 | D9: =IFERROR(DEC2HEX(MOD((HEX2DEC('Leaf Green Seeds'!D9) - 11 ),65536),4),"") -> 3FB9 | E9: =IFERROR(DEC2HEX(MOD((HEX2DEC('Leaf Green Seeds'!E9) - 9 ),65536),4),"") -> 3FB8 | F9: =IFERROR(DEC2HEX(MOD((HEX2DEC('Leaf Green Seeds'!F9) + 3 ),65536),4),"") -> 3FC7 | G9: =IFERROR(DEC2HEX(MOD((HEX2DEC('Leaf Green Seeds'!G9) - 11 ),65536),4),"") -> 3FD7 | H9: =IFERROR(DEC2HEX(MOD((HEX2DEC('Leaf Green Seeds'!H9) - 9 ),65536),4),"") -> 3FD7 | I9: =IFERROR(DEC2HEX(MOD((HEX2DEC('Leaf Green Seeds'!I9) + 3 ),65536),4),"") -> 3FE5 | J9: =IFERROR(DEC2HEX(MOD((HEX2DEC('Leaf Green Seeds'!J9) - 11 ),65536),4),"") -> 3FA5 | K9: =IFERROR(DEC2HEX(MOD((HEX2DEC('Leaf Green Seeds'!K9) - 9 ),65536),4),"") -> 3FA5 | L9: =IFERROR(DEC2HEX(MOD((HEX2DEC('Leaf Green Seeds'!L9) + 3 ),65536),4),"") -> 3FBE | M9: =IFERROR(DEC2HEX(MOD((HEX2DEC('Leaf Green Seeds'!M9) - 11 ),65536),4),"") -> 3FC4 | N9: =IFERROR(DEC2HEX(MOD((HEX2DEC('Leaf Green Seeds'!N9) - 9 ),65536),4),"") -> 3FCF | O9: =IFERROR(DEC2HEX(MOD((HEX2DEC('Leaf Green Seeds'!O9) + 3 ),65536),4),"") -> 3FDC
A10: 8 | B10: 33872 | C10: 34868 | D10: =IFERROR(DEC2HEX(MOD((HEX2DEC('Leaf Green Seeds'!D10) - 11 ),65536),4),"") -> 96CB | E10: =IFERROR(DEC2HEX(MOD((HEX2DEC('Leaf Green Seeds'!E10) - 9 ),65536),4),"") -> 96CB | F10: =IFERROR(DEC2HEX(MOD((HEX2DEC('Leaf Green Seeds'!F10) + 3 ),65536),4),"") -> 96E1 | G10: =IFERROR(DEC2HEX(MOD((HEX2DEC('Leaf Green Seeds'!G10) - 11 ),65536),4),"") -> 96F1 | H10: =IFERROR(DEC2HEX(MOD((HEX2DEC('Leaf Green Seeds'!H10) - 9 ),65536),4),"") -> 96F4 | I10: =IFERROR(DEC2HEX(MOD((HEX2DEC('Leaf Green Seeds'!I10) + 3 ),65536),4),"") -> 96FF | J10: =IFERROR(DEC2HEX(MOD((HEX2DEC('Leaf Green Seeds'!J10) - 11 ),65536),4),"") -> 96CB | K10: =IFERROR(DEC2HEX(MOD((HEX2DEC('Leaf Green Seeds'!K10) - 9 ),65536),4),"") -> 96CD | L10: =IFERROR(DEC2HEX(MOD((HEX2DEC('Leaf Green Seeds'!L10) + 3 ),65536),4),"") -> 96DC | M10: =IFERROR(DEC2HEX(MOD((HEX2DEC('Leaf Green Seeds'!M10) - 11 ),65536),4),"") -> 96E1 | N10: =IFERROR(DEC2HEX(MOD((HEX2DEC('Leaf Green Seeds'!N10) - 9 ),65536),4),"") -> 96E9 | O10: =IFERROR(DEC2HEX(MOD((HEX2DEC('Leaf Green Seeds'!O10) + 3 ),65536),4),"") -> 96FA
A11: 9 | B11: 33888 | C11: 34884 | D11: =IFERROR(DEC2HEX(MOD((HEX2DEC('Leaf Green Seeds'!D11) - 11 ),65536),4),"") -> D4B6 | E11: =IFERROR(DEC2HEX(MOD((HEX2DEC('Leaf Green Seeds'!E11) - 9 ),65536),4),"") -> D4B6 | F11: =IFERROR(DEC2HEX(MOD((HEX2DEC('Leaf Green Seeds'!F11) + 3 ),65536),4),"") -> D4CD | G11: =IFERROR(DEC2HEX(MOD((HEX2DEC('Leaf Green Seeds'!G11) - 11 ),65536),4),"") -> D4B6 | H11: =IFERROR(DEC2HEX(MOD((HEX2DEC('Leaf Green Seeds'!H11) - 9 ),65536),4),"") -> D4B6 | I11: =IFERROR(DEC2HEX(MOD((HEX2DEC('Leaf Green Seeds'!I11) + 3 ),65536),4),"") -> D4C4 | J11: =IFERROR(DEC2HEX(MOD((HEX2DEC('Leaf Green Seeds'!J11) - 11 ),65536),4),"") -> D4AE | K11: =IFERROR(DEC2HEX(MOD((HEX2DEC('Leaf Green Seeds'!K11) - 9 ),65536),4),"") -> D4B6 | L11: =IFERROR(DEC2HEX(MOD((HEX2DEC('Leaf Green Seeds'!L11) + 3 ),65536),4),"") -> D4BC | M11: =IFERROR(DEC2HEX(MOD((HEX2DEC('Leaf Green Seeds'!M11) - 11 ),65536),4),"") -> D4B6 | N11: =IFERROR(DEC2HEX(MOD((HEX2DEC('Leaf Green Seeds'!N11) - 9 ),65536),4),"") -> D4AE | O11: =IFERROR(DEC2HEX(MOD((HEX2DEC('Leaf Green Seeds'!O11) + 3 ),65536),4),"") -> D4BC
A12: 10 | B12: 33904 | C12: 34900 | D12: =IFERROR(DEC2HEX(MOD((HEX2DEC('Leaf Green Seeds'!D12) - 11 ),65536),4),"") -> 1E83 | E12: =IFERROR(DEC2HEX(MOD((HEX2DEC('Leaf Green Seeds'!E12) - 9 ),65536),4),"") -> 1E83 | F12: =IFERROR(DEC2HEX(MOD((HEX2DEC('Leaf Green Seeds'!F12) + 3 ),65536),4),"") -> 1E9B | G12: =IFERROR(DEC2HEX(MOD((HEX2DEC('Leaf Green Seeds'!G12) - 11 ),65536),4),"") -> 1EA2 | H12: =IFERROR(DEC2HEX(MOD((HEX2DEC('Leaf Green Seeds'!H12) - 9 ),65536),4),"") -> 1EA2 | I12: =IFERROR(DEC2HEX(MOD((HEX2DEC('Leaf Green Seeds'!I12) + 3 ),65536),4),"") -> 1EB9 | J12: =IFERROR(DEC2HEX(MOD((HEX2DEC('Leaf Green Seeds'!J12) - 11 ),65536),4),"") -> 1E7B | K12: =IFERROR(DEC2HEX(MOD((HEX2DEC('Leaf Green Seeds'!K12) - 9 ),65536),4),"") -> 1E7B | L12: =IFERROR(DEC2HEX(MOD((HEX2DEC('Leaf Green Seeds'!L12) + 3 ),65536),4),"") -> 1E93 | M12: =IFERROR(DEC2HEX(MOD((HEX2DEC('Leaf Green Seeds'!M12) - 11 ),65536),4),"") -> 1EA3 | N12: =IFERROR(DEC2HEX(MOD((HEX2DEC('Leaf Green Seeds'!N12) - 9 ),65536),4),"") -> 1E9A | O12: =IFERROR(DEC2HEX(MOD((HEX2DEC('Leaf Green Seeds'!O12) + 3 ),65536),4),"") -> 1EB1
A13: 11 | B13: 33920 | C13: 34916 | D13: =IFERROR(DEC2HEX(MOD((HEX2DEC('Leaf Green Seeds'!D13) - 11 ),65536),4),"") -> 9230 | E13: =IFERROR(DEC2HEX(MOD((HEX2DEC('Leaf Green Seeds'!E13) - 9 ),65536),4),"") -> 9228 | F13: =IFERROR(DEC2HEX(MOD((HEX2DEC('Leaf Green Seeds'!F13) + 3 ),65536),4),"") -> 9240 | G13: =IFERROR(DEC2HEX(MOD((HEX2DEC('Leaf Green Seeds'!G13) - 11 ),65536),4),"") -> 9230 | H13: =IFERROR(DEC2HEX(MOD((HEX2DEC('Leaf Green Seeds'!H13) - 9 ),65536),4),"") -> 9230 | I13: =IFERROR(DEC2HEX(MOD((HEX2DEC('Leaf Green Seeds'!I13) + 3 ),65536),4),"") -> 923E | J13: =IFERROR(DEC2HEX(MOD((HEX2DEC('Leaf Green Seeds'!J13) - 11 ),65536),4),"") -> 9220 | K13: =IFERROR(DEC2HEX(MOD((HEX2DEC('Leaf Green Seeds'!K13) - 9 ),65536),4),"") -> 9228 | L13: =IFERROR(DEC2HEX(MOD((HEX2DEC('Leaf Green Seeds'!L13) + 3 ),65536),4),"") -> 922E | M13: =IFERROR(DEC2HEX(MOD((HEX2DEC('Leaf Green Seeds'!M13) - 11 ),65536),4),"") -> 9228 | N13: =IFERROR(DEC2HEX(MOD((HEX2DEC('Leaf Green Seeds'!N13) - 9 ),65536),4),"") -> 9220 | O13: =IFERROR(DEC2HEX(MOD((HEX2DEC('Leaf Green Seeds'!O13) + 3 ),65536),4),"") -> 922E
A14: 12 | B14: 33936 | C14: 34932 | D14: =IFERROR(DEC2HEX(MOD((HEX2DEC('Leaf Green Seeds'!D14) - 11 ),65536),4),"") -> CF01 | E14: =IFERROR(DEC2HEX(MOD((HEX2DEC('Leaf Green Seeds'!E14) - 9 ),65536),4),"") -> CEFA | F14: =IFERROR(DEC2HEX(MOD((HEX2DEC('Leaf Green Seeds'!F14) + 3 ),65536),4),"") -> CF08 | G14: =IFERROR(DEC2HEX(MOD((HEX2DEC('Leaf Green Seeds'!G14) - 11 ),65536),4),"") -> CF1D | H14: =IFERROR(DEC2HEX(MOD((HEX2DEC('Leaf Green Seeds'!H14) - 9 ),65536),4),"") -> CF11 | I14: =IFERROR(DEC2HEX(MOD((HEX2DEC('Leaf Green Seeds'!I14) + 3 ),65536),4),"") -> CF1F | J14: =IFERROR(DEC2HEX(MOD((HEX2DEC('Leaf Green Seeds'!J14) - 11 ),65536),4),"") -> CEFB | K14: =IFERROR(DEC2HEX(MOD((HEX2DEC('Leaf Green Seeds'!K14) - 9 ),65536),4),"") -> CEF2 | L14: =IFERROR(DEC2HEX(MOD((HEX2DEC('Leaf Green Seeds'!L14) + 3 ),65536),4),"") -> CF0A | M14: =IFERROR(DEC2HEX(MOD((HEX2DEC('Leaf Green Seeds'!M14) - 11 ),65536),4),"") -> CF14 | N14: =IFERROR(DEC2HEX(MOD((HEX2DEC('Leaf Green Seeds'!N14) - 9 ),65536),4),"") -> CF11 | O14: =IFERROR(DEC2HEX(MOD((HEX2DEC('Leaf Green Seeds'!O14) + 3 ),65536),4),"") -> CF1F
... A2440: 2438 | B2440: 74638 | C2440: 75632 | D2440: =IFERROR(DEC2HEX(MOD((HEX2DEC('Leaf Green Seeds'!D2440) - 11 ),65536),4),"") -> BC97 | E2440: =IFERROR(DEC2HEX(MOD((HEX2DEC('Leaf Green Seeds'!E2440) - 9 ),65536),4),"") -> BC98 | F2440: =IFERROR(DEC2HEX(MOD((HEX2DEC('Leaf Green Seeds'!F2440) + 3 ),65536),4),"") -> BCA5 | G2440: =IFERROR(DEC2HEX(MOD((HEX2DEC('Leaf Green Seeds'!G2440) - 11 ),65536),4),"") -> BCB4 | H2440: =IFERROR(DEC2HEX(MOD((HEX2DEC('Leaf Green Seeds'!H2440) - 9 ),65536),4),"") -> BCB4 | I2440: =IFERROR(DEC2HEX(MOD((HEX2DEC('Leaf Green Seeds'!I2440) + 3 ),65536),4),"") -> BCBB | J2440: =IFERROR(DEC2HEX(MOD((HEX2DEC('Leaf Green Seeds'!J2440) - 11 ),65536),4),"") | K2440: =IFERROR(DEC2HEX(MOD((HEX2DEC('Leaf Green Seeds'!K2440) - 9 ),65536),4),"") | L2440: =IFERROR(DEC2HEX(MOD((HEX2DEC('Leaf Green Seeds'!L2440) + 3 ),65536),4),"") | M2440: =IFERROR(DEC2HEX(MOD((HEX2DEC('Leaf Green Seeds'!M2440) - 11 ),65536),4),"") | N2440: =IFERROR(DEC2HEX(MOD((HEX2DEC('Leaf Green Seeds'!N2440) - 9 ),65536),4),"") | O2440: =IFERROR(DEC2HEX(MOD((HEX2DEC('Leaf Green Seeds'!O2440) + 3 ),65536),4),"") -> BCBD

Sheet Held Blackout R Button
A1: Hold the R Button during the black screen right before the shooting star from the intro appears. You can let go of it as soon you can see the leaves on the title screen.
A2: # | B2: Intro Time ms (GBA) | C2: Intro Time ms (NDS) | D2: MONO/LR | E2: MONO/L=A | F2: MONO/HELP | G2: STEREO/LR | H2: STEREO/L=A | I2: STEREO/HELP | J2: MONO/LR, Start | K2: MONO/L=A, Start | L2: MONO/HELP, Start | M2: STEREO/LR, Start | N2: STEREO/L=A, Start | O2: STEREO/HELP, Start
A3: 1 | B3: 33752 | C3: 34748 | D3: =IFERROR(DEC2HEX(MOD((HEX2DEC('Leaf Green Seeds'!D3) - 23 ),65536),4),"") -> A069 | E3: =IFERROR(DEC2HEX(MOD((HEX2DEC('Leaf Green Seeds'!E3) - 24 ),65536),4),"") -> A05C | F3: =IFERROR(DEC2HEX(MOD((HEX2DEC('Leaf Green Seeds'!F3) - 23 ),65536),4),"") -> A069 | G3: =IFERROR(DEC2HEX(MOD((HEX2DEC('Leaf Green Seeds'!G3) - 23 ),65536),4),"") -> A094 | H3: =IFERROR(DEC2HEX(MOD((HEX2DEC('Leaf Green Seeds'!H3) - 24 ),65536),4),"") -> A09E | I3: =IFERROR(DEC2HEX(MOD((HEX2DEC('Leaf Green Seeds'!I3) - 23 ),65536),4),"") -> A094 | J3: =IFERROR(DEC2HEX(MOD((HEX2DEC('Leaf Green Seeds'!J3) - 23 ),65536),4),"") -> A05F | K3: =IFERROR(DEC2HEX(MOD((HEX2DEC('Leaf Green Seeds'!K3) - 24 ),65536),4),"") -> A05E | L3: =IFERROR(DEC2HEX(MOD((HEX2DEC('Leaf Green Seeds'!L3) - 23 ),65536),4),"") -> A056 | M3: =IFERROR(DEC2HEX(MOD((HEX2DEC('Leaf Green Seeds'!M3) - 23 ),65536),4),"") -> A098 | N3: =IFERROR(DEC2HEX(MOD((HEX2DEC('Leaf Green Seeds'!N3) - 24 ),65536),4),"") -> A094 | O3: =IFERROR(DEC2HEX(MOD((HEX2DEC('Leaf Green Seeds'!O3) - 23 ),65536),4),"") -> A095
A4: 2 | B4: 33768 | C4: 34764 | D4: =IFERROR(DEC2HEX(MOD((HEX2DEC('Leaf Green Seeds'!D4) - 23 ),65536),4),"") -> ECB0 | E4: =IFERROR(DEC2HEX(MOD((HEX2DEC('Leaf Green Seeds'!E4) - 24 ),65536),4),"") -> ECAB | F4: =IFERROR(DEC2HEX(MOD((HEX2DEC('Leaf Green Seeds'!F4) - 23 ),65536),4),"") -> ECAF | G4: =IFERROR(DEC2HEX(MOD((HEX2DEC('Leaf Green Seeds'!G4) - 23 ),65536),4),"") -> ECA6 | H4: =IFERROR(DEC2HEX(MOD((HEX2DEC('Leaf Green Seeds'!H4) - 24 ),65536),4),"") -> ECA3 | I4: =IFERROR(DEC2HEX(MOD((HEX2DEC('Leaf Green Seeds'!I4) - 23 ),65536),4),"") -> ECA6 | J4: =IFERROR(DEC2HEX(MOD((HEX2DEC('Leaf Green Seeds'!J4) - 23 ),65536),4),"") -> EC9E | K4: =IFERROR(DEC2HEX(MOD((HEX2DEC('Leaf Green Seeds'!K4) - 24 ),65536),4),"") -> EC9B | L4: =IFERROR(DEC2HEX(MOD((HEX2DEC('Leaf Green Seeds'!L4) - 23 ),65536),4),"") -> EC9E | M4: =IFERROR(DEC2HEX(MOD((HEX2DEC('Leaf Green Seeds'!M4) - 23 ),65536),4),"") -> ECA7 | N4: =IFERROR(DEC2HEX(MOD((HEX2DEC('Leaf Green Seeds'!N4) - 24 ),65536),4),"") -> ECA6 | O4: =IFERROR(DEC2HEX(MOD((HEX2DEC('Leaf Green Seeds'!O4) - 23 ),65536),4),"") -> EC9E
A5: 3 | B5: 33784 | C5: 34780 | D5: =IFERROR(DEC2HEX(MOD((HEX2DEC('Leaf Green Seeds'!D5) - 23 ),65536),4),"") -> 3696 | E5: =IFERROR(DEC2HEX(MOD((HEX2DEC('Leaf Green Seeds'!E5) - 24 ),65536),4),"") -> 368E | F5: =IFERROR(DEC2HEX(MOD((HEX2DEC('Leaf Green Seeds'!F5) - 23 ),65536),4),"") -> 3691 | G5: =IFERROR(DEC2HEX(MOD((HEX2DEC('Leaf Green Seeds'!G5) - 23 ),65536),4),"") -> 36AF | H5: =IFERROR(DEC2HEX(MOD((HEX2DEC('Leaf Green Seeds'!H5) - 24 ),65536),4),"") -> 36B6 | I5: =IFERROR(DEC2HEX(MOD((HEX2DEC('Leaf Green Seeds'!I5) - 23 ),65536),4),"") -> 36B9 | J5: =IFERROR(DEC2HEX(MOD((HEX2DEC('Leaf Green Seeds'!J5) - 23 ),65536),4),"") -> 368E | K5: =IFERROR(DEC2HEX(MOD((HEX2DEC('Leaf Green Seeds'!K5) - 24 ),65536),4),"") -> 368B | L5: =IFERROR(DEC2HEX(MOD((HEX2DEC('Leaf Green Seeds'!L5) - 23 ),65536),4),"") -> 3689 | M5: =IFERROR(DEC2HEX(MOD((HEX2DEC('Leaf Green Seeds'!M5) - 23 ),65536),4),"") -> 36A7 | N5: =IFERROR(DEC2HEX(MOD((HEX2DEC('Leaf Green Seeds'!N5) - 24 ),65536),4),"") -> 36AE | O5: =IFERROR(DEC2HEX(MOD((HEX2DEC('Leaf Green Seeds'!O5) - 23 ),65536),4),"") -> 36A7
A6: 4 | B6: 33808 | C6: 34804 | D6: =IFERROR(DEC2HEX(MOD((HEX2DEC('Leaf Green Seeds'!D6) - 23 ),65536),4),"") -> 7F24 | E6: =IFERROR(DEC2HEX(MOD((HEX2DEC('Leaf Green Seeds'!E6) - 24 ),65536),4),"") -> 7F29 | F6: =IFERROR(DEC2HEX(MOD((HEX2DEC('Leaf Green Seeds'!F6) - 23 ),65536),4),"") -> 7F2D | G6: =IFERROR(DEC2HEX(MOD((HEX2DEC('Leaf Green Seeds'!G6) - 23 ),65536),4),"") -> 7F24 | H6: =IFERROR(DEC2HEX(MOD((HEX2DEC('Leaf Green Seeds'!H6) - 24 ),65536),4),"") -> 7F29 | I6: =IFERROR(DEC2HEX(MOD((HEX2DEC('Leaf Green Seeds'!I6) - 23 ),65536),4),"") -> 7F2D | J6: =IFERROR(DEC2HEX(MOD((HEX2DEC('Leaf Green Seeds'!J6) - 23 ),65536),4),"") -> 7F25 | K6: =IFERROR(DEC2HEX(MOD((HEX2DEC('Leaf Green Seeds'!K6) - 24 ),65536),4),"") -> 7F21 | L6: =IFERROR(DEC2HEX(MOD((HEX2DEC('Leaf Green Seeds'!L6) - 23 ),65536),4),"") -> 7F25 | M6: =IFERROR(DEC2HEX(MOD((HEX2DEC('Leaf Green Seeds'!M6) - 23 ),65536),4),"") -> 7F25 | N6: =IFERROR(DEC2HEX(MOD((HEX2DEC('Leaf Green Seeds'!N6) - 24 ),65536),4),"") -> 7F21 | O6: =IFERROR(DEC2HEX(MOD((HEX2DEC('Leaf Green Seeds'!O6) - 23 ),65536),4),"") -> 7F1C
A7: 5 | B7: 33824 | C7: 34820 | D7: =IFERROR(DEC2HEX(MOD((HEX2DEC('Leaf Green Seeds'!D7) - 23 ),65536),4),"") -> C919 | E7: =IFERROR(DEC2HEX(MOD((HEX2DEC('Leaf Green Seeds'!E7) - 24 ),65536),4),"") -> C913 | F7: =IFERROR(DEC2HEX(MOD((HEX2DEC('Leaf Green Seeds'!F7) - 23 ),65536),4),"") -> C918 | G7: =IFERROR(DEC2HEX(MOD((HEX2DEC('Leaf Green Seeds'!G7) - 23 ),65536),4),"") -> C93C | H7: =IFERROR(DEC2HEX(MOD((HEX2DEC('Leaf Green Seeds'!H7) - 24 ),65536),4),"") -> C92B | I7: =IFERROR(DEC2HEX(MOD((HEX2DEC('Leaf Green Seeds'!I7) - 23 ),65536),4),"") -> C93A | J7: =IFERROR(DEC2HEX(MOD((HEX2DEC('Leaf Green Seeds'!J7) - 23 ),65536),4),"") -> C911 | K7: =IFERROR(DEC2HEX(MOD((HEX2DEC('Leaf Green Seeds'!K7) - 24 ),65536),4),"") -> C90B | L7: =IFERROR(DEC2HEX(MOD((HEX2DEC('Leaf Green Seeds'!L7) - 23 ),65536),4),"") -> C909 | M7: =IFERROR(DEC2HEX(MOD((HEX2DEC('Leaf Green Seeds'!M7) - 23 ),65536),4),"") -> C930 | N7: =IFERROR(DEC2HEX(MOD((HEX2DEC('Leaf Green Seeds'!N7) - 24 ),65536),4),"") -> C923 | O7: =IFERROR(DEC2HEX(MOD((HEX2DEC('Leaf Green Seeds'!O7) - 23 ),65536),4),"") -> C926
A8: 6 | B8: 33840 | C8: 34836 | D8: =IFERROR(DEC2HEX(MOD((HEX2DEC('Leaf Green Seeds'!D8) - 23 ),65536),4),"") -> 1198 | E8: =IFERROR(DEC2HEX(MOD((HEX2DEC('Leaf Green Seeds'!E8) - 24 ),65536),4),"") -> 119C | F8: =IFERROR(DEC2HEX(MOD((HEX2DEC('Leaf Green Seeds'!F8) - 23 ),65536),4),"") -> 1198 | G8: =IFERROR(DEC2HEX(MOD((HEX2DEC('Leaf Green Seeds'!G8) - 23 ),65536),4),"") -> 1198 | H8: =IFERROR(DEC2HEX(MOD((HEX2DEC('Leaf Green Seeds'!H8) - 24 ),65536),4),"") -> 1193 | I8: =IFERROR(DEC2HEX(MOD((HEX2DEC('Leaf Green Seeds'!I8) - 23 ),65536),4),"") -> 1198 | J8: =IFERROR(DEC2HEX(MOD((HEX2DEC('Leaf Green Seeds'!J8) - 23 ),65536),4),"") -> 119B | K8: =IFERROR(DEC2HEX(MOD((HEX2DEC('Leaf Green Seeds'!K8) - 24 ),65536),4),"") -> 118B | L8: =IFERROR(DEC2HEX(MOD((HEX2DEC('Leaf Green Seeds'!L8) - 23 ),65536),4),"") -> 119B | M8: =IFERROR(DEC2HEX(MOD((HEX2DEC('Leaf Green Seeds'!M8) - 23 ),65536),4),"") -> 118F | N8: =IFERROR(DEC2HEX(MOD((HEX2DEC('Leaf Green Seeds'!N8) - 24 ),65536),4),"") -> 1194 | O8: =IFERROR(DEC2HEX(MOD((HEX2DEC('Leaf Green Seeds'!O8) - 23 ),65536),4),"") -> 118F
A9: 7 | B9: 33856 | C9: 34852 | D9: =IFERROR(DEC2HEX(MOD((HEX2DEC('Leaf Green Seeds'!D9) - 23 ),65536),4),"") -> 3FAD | E9: =IFERROR(DEC2HEX(MOD((HEX2DEC('Leaf Green Seeds'!E9) - 24 ),65536),4),"") -> 3FA9 | F9: =IFERROR(DEC2HEX(MOD((HEX2DEC('Leaf Green Seeds'!F9) - 23 ),65536),4),"") -> 3FAD | G9: =IFERROR(DEC2HEX(MOD((HEX2DEC('Leaf Green Seeds'!G9) - 23 ),65536),4),"") -> 3FCB | H9: =IFERROR(DEC2HEX(MOD((HEX2DEC('Leaf Green Seeds'!H9) - 24 ),65536),4),"") -> 3FC8 | I9: =IFERROR(DEC2HEX(MOD((HEX2DEC('Leaf Green Seeds'!I9) - 23 ),65536),4),"") -> 3FCB | J9: =IFERROR(DEC2HEX(MOD((HEX2DEC('Leaf Green Seeds'!J9) - 23 ),65536),4),"") -> 3F99 | K9: =IFERROR(DEC2HEX(MOD((HEX2DEC('Leaf Green Seeds'!K9) - 24 ),65536),4),"") -> 3F96 | L9: =IFERROR(DEC2HEX(MOD((HEX2DEC('Leaf Green Seeds'!L9) - 23 ),65536),4),"") -> 3FA4 | M9: =IFERROR(DEC2HEX(MOD((HEX2DEC('Leaf Green Seeds'!M9) - 23 ),65536),4),"") -> 3FB8 | N9: =IFERROR(DEC2HEX(MOD((HEX2DEC('Leaf Green Seeds'!N9) - 24 ),65536),4),"") -> 3FC0 | O9: =IFERROR(DEC2HEX(MOD((HEX2DEC('Leaf Green Seeds'!O9) - 23 ),65536),4),"") -> 3FC2
A10: 8 | B10: 33872 | C10: 34868 | D10: =IFERROR(DEC2HEX(MOD((HEX2DEC('Leaf Green Seeds'!D10) - 23 ),65536),4),"") -> 96BF | E10: =IFERROR(DEC2HEX(MOD((HEX2DEC('Leaf Green Seeds'!E10) - 24 ),65536),4),"") -> 96BC | F10: =IFERROR(DEC2HEX(MOD((HEX2DEC('Leaf Green Seeds'!F10) - 23 ),65536),4),"") -> 96C7 | G10: =IFERROR(DEC2HEX(MOD((HEX2DEC('Leaf Green Seeds'!G10) - 23 ),65536),4),"") -> 96E5 | H10: =IFERROR(DEC2HEX(MOD((HEX2DEC('Leaf Green Seeds'!H10) - 24 ),65536),4),"") -> 96E5 | I10: =IFERROR(DEC2HEX(MOD((HEX2DEC('Leaf Green Seeds'!I10) - 23 ),65536),4),"") -> 96E5 | J10: =IFERROR(DEC2HEX(MOD((HEX2DEC('Leaf Green Seeds'!J10) - 23 ),65536),4),"") -> 96BF | K10: =IFERROR(DEC2HEX(MOD((HEX2DEC('Leaf Green Seeds'!K10) - 24 ),65536),4),"") -> 96BE | L10: =IFERROR(DEC2HEX(MOD((HEX2DEC('Leaf Green Seeds'!L10) - 23 ),65536),4),"") -> 96C2 | M10: =IFERROR(DEC2HEX(MOD((HEX2DEC('Leaf Green Seeds'!M10) - 23 ),65536),4),"") -> 96D5 | N10: =IFERROR(DEC2HEX(MOD((HEX2DEC('Leaf Green Seeds'!N10) - 24 ),65536),4),"") -> 96DA | O10: =IFERROR(DEC2HEX(MOD((HEX2DEC('Leaf Green Seeds'!O10) - 23 ),65536),4),"") -> 96E0
A11: 9 | B11: 33888 | C11: 34884 | D11: =IFERROR(DEC2HEX(MOD((HEX2DEC('Leaf Green Seeds'!D11) - 23 ),65536),4),"") -> D4AA | E11: =IFERROR(DEC2HEX(MOD((HEX2DEC('Leaf Green Seeds'!E11) - 24 ),65536),4),"") -> D4A7 | F11: =IFERROR(DEC2HEX(MOD((HEX2DEC('Leaf Green Seeds'!F11) - 23 ),65536),4),"") -> D4B3 | G11: =IFERROR(DEC2HEX(MOD((HEX2DEC('Leaf Green Seeds'!G11) - 23 ),65536),4),"") -> D4AA | H11: =IFERROR(DEC2HEX(MOD((HEX2DEC('Leaf Green Seeds'!H11) - 24 ),65536),4),"") -> D4A7 | I11: =IFERROR(DEC2HEX(MOD((HEX2DEC('Leaf Green Seeds'!I11) - 23 ),65536),4),"") -> D4AA | J11: =IFERROR(DEC2HEX(MOD((HEX2DEC('Leaf Green Seeds'!J11) - 23 ),65536),4),"") -> D4A2 | K11: =IFERROR(DEC2HEX(MOD((HEX2DEC('Leaf Green Seeds'!K11) - 24 ),65536),4),"") -> D4A7 | L11: =IFERROR(DEC2HEX(MOD((HEX2DEC('Leaf Green Seeds'!L11) - 23 ),65536),4),"") -> D4A2 | M11: =IFERROR(DEC2HEX(MOD((HEX2DEC('Leaf Green Seeds'!M11) - 23 ),65536),4),"") -> D4AA | N11: =IFERROR(DEC2HEX(MOD((HEX2DEC('Leaf Green Seeds'!N11) - 24 ),65536),4),"") -> D49F | O11: =IFERROR(DEC2HEX(MOD((HEX2DEC('Leaf Green Seeds'!O11) - 23 ),65536),4),"") -> D4A2
A12: 10 | B12: 33904 | C12: 34900 | D12: =IFERROR(DEC2HEX(MOD((HEX2DEC('Leaf Green Seeds'!D12) - 23 ),65536),4),"") -> 1E77 | E12: =IFERROR(DEC2HEX(MOD((HEX2DEC('Leaf Green Seeds'!E12) - 24 ),65536),4),"") -> 1E74 | F12: =IFERROR(DEC2HEX(MOD((HEX2DEC('Leaf Green Seeds'!F12) - 23 ),65536),4),"") -> 1E81 | G12: =IFERROR(DEC2HEX(MOD((HEX2DEC('Leaf Green Seeds'!G12) - 23 ),65536),4),"") -> 1E96 | H12: =IFERROR(DEC2HEX(MOD((HEX2DEC('Leaf Green Seeds'!H12) - 24 ),65536),4),"") -> 1E93 | I12: =IFERROR(DEC2HEX(MOD((HEX2DEC('Leaf Green Seeds'!I12) - 23 ),65536),4),"") -> 1E9F | J12: =IFERROR(DEC2HEX(MOD((HEX2DEC('Leaf Green Seeds'!J12) - 23 ),65536),4),"") -> 1E6F | K12: =IFERROR(DEC2HEX(MOD((HEX2DEC('Leaf Green Seeds'!K12) - 24 ),65536),4),"") -> 1E6C | L12: =IFERROR(DEC2HEX(MOD((HEX2DEC('Leaf Green Seeds'!L12) - 23 ),65536),4),"") -> 1E79 | M12: =IFERROR(DEC2HEX(MOD((HEX2DEC('Leaf Green Seeds'!M12) - 23 ),65536),4),"") -> 1E97 | N12: =IFERROR(DEC2HEX(MOD((HEX2DEC('Leaf Green Seeds'!N12) - 24 ),65536),4),"") -> 1E8B | O12: =IFERROR(DEC2HEX(MOD((HEX2DEC('Leaf Green Seeds'!O12) - 23 ),65536),4),"") -> 1E97
A13: 11 | B13: 33920 | C13: 34916 | D13: =IFERROR(DEC2HEX(MOD((HEX2DEC('Leaf Green Seeds'!D13) - 23 ),65536),4),"") -> 9224 | E13: =IFERROR(DEC2HEX(MOD((HEX2DEC('Leaf Green Seeds'!E13) - 24 ),65536),4),"") -> 9219 | F13: =IFERROR(DEC2HEX(MOD((HEX2DEC('Leaf Green Seeds'!F13) - 23 ),65536),4),"") -> 9226 | G13: =IFERROR(DEC2HEX(MOD((HEX2DEC('Leaf Green Seeds'!G13) - 23 ),65536),4),"") -> 9224 | H13: =IFERROR(DEC2HEX(MOD((HEX2DEC('Leaf Green Seeds'!H13) - 24 ),65536),4),"") -> 9221 | I13: =IFERROR(DEC2HEX(MOD((HEX2DEC('Leaf Green Seeds'!I13) - 23 ),65536),4),"") -> 9224 | J13: =IFERROR(DEC2HEX(MOD((HEX2DEC('Leaf Green Seeds'!J13) - 23 ),65536),4),"") -> 9214 | K13: =IFERROR(DEC2HEX(MOD((HEX2DEC('Leaf Green Seeds'!K13) - 24 ),65536),4),"") -> 9219 | L13: =IFERROR(DEC2HEX(MOD((HEX2DEC('Leaf Green Seeds'!L13) - 23 ),65536),4),"") -> 9214 | M13: =IFERROR(DEC2HEX(MOD((HEX2DEC('Leaf Green Seeds'!M13) - 23 ),65536),4),"") -> 921C | N13: =IFERROR(DEC2HEX(MOD((HEX2DEC('Leaf Green Seeds'!N13) - 24 ),65536),4),"") -> 9211 | O13: =IFERROR(DEC2HEX(MOD((HEX2DEC('Leaf Green Seeds'!O13) - 23 ),65536),4),"") -> 9214
A14: 12 | B14: 33936 | C14: 34932 | D14: =IFERROR(DEC2HEX(MOD((HEX2DEC('Leaf Green Seeds'!D14) - 23 ),65536),4),"") -> CEF5 | E14: =IFERROR(DEC2HEX(MOD((HEX2DEC('Leaf Green Seeds'!E14) - 24 ),65536),4),"") -> CEEB | F14: =IFERROR(DEC2HEX(MOD((HEX2DEC('Leaf Green Seeds'!F14) - 23 ),65536),4),"") -> CEEE | G14: =IFERROR(DEC2HEX(MOD((HEX2DEC('Leaf Green Seeds'!G14) - 23 ),65536),4),"") -> CF11 | H14: =IFERROR(DEC2HEX(MOD((HEX2DEC('Leaf Green Seeds'!H14) - 24 ),65536),4),"") -> CF02 | I14: =IFERROR(DEC2HEX(MOD((HEX2DEC('Leaf Green Seeds'!I14) - 23 ),65536),4),"") -> CF05 | J14: =IFERROR(DEC2HEX(MOD((HEX2DEC('Leaf Green Seeds'!J14) - 23 ),65536),4),"") -> CEEF | K14: =IFERROR(DEC2HEX(MOD((HEX2DEC('Leaf Green Seeds'!K14) - 24 ),65536),4),"") -> CEE3 | L14: =IFERROR(DEC2HEX(MOD((HEX2DEC('Leaf Green Seeds'!L14) - 23 ),65536),4),"") -> CEF0 | M14: =IFERROR(DEC2HEX(MOD((HEX2DEC('Leaf Green Seeds'!M14) - 23 ),65536),4),"") -> CF08 | N14: =IFERROR(DEC2HEX(MOD((HEX2DEC('Leaf Green Seeds'!N14) - 24 ),65536),4),"") -> CF02 | O14: =IFERROR(DEC2HEX(MOD((HEX2DEC('Leaf Green Seeds'!O14) - 23 ),65536),4),"") -> CF05
... A2440: 2438 | B2440: 74638 | C2440: 75632 | D2440: =IFERROR(DEC2HEX(MOD((HEX2DEC('Leaf Green Seeds'!D2440) - 23 ),65536),4),"") -> BC8B | E2440: =IFERROR(DEC2HEX(MOD((HEX2DEC('Leaf Green Seeds'!E2440) - 24 ),65536),4),"") -> BC89 | F2440: =IFERROR(DEC2HEX(MOD((HEX2DEC('Leaf Green Seeds'!F2440) - 23 ),65536),4),"") -> BC8B | G2440: =IFERROR(DEC2HEX(MOD((HEX2DEC('Leaf Green Seeds'!G2440) - 23 ),65536),4),"") -> BCA8 | H2440: =IFERROR(DEC2HEX(MOD((HEX2DEC('Leaf Green Seeds'!H2440) - 24 ),65536),4),"") -> BCA5 | I2440: =IFERROR(DEC2HEX(MOD((HEX2DEC('Leaf Green Seeds'!I2440) - 23 ),65536),4),"") -> BCA1 | J2440: =IFERROR(DEC2HEX(MOD((HEX2DEC('Leaf Green Seeds'!J2440) - 23 ),65536),4),"") | K2440: =IFERROR(DEC2HEX(MOD((HEX2DEC('Leaf Green Seeds'!K2440) - 24 ),65536),4),"") | L2440: =IFERROR(DEC2HEX(MOD((HEX2DEC('Leaf Green Seeds'!L2440) - 23 ),65536),4),"") | M2440: =IFERROR(DEC2HEX(MOD((HEX2DEC('Leaf Green Seeds'!M2440) - 23 ),65536),4),"") | N2440: =IFERROR(DEC2HEX(MOD((HEX2DEC('Leaf Green Seeds'!N2440) - 24 ),65536),4),"") | O2440: =IFERROR(DEC2HEX(MOD((HEX2DEC('Leaf Green Seeds'!O2440) - 23 ),65536),4),"") -> BCA3

Sheet Useful Seeds Old
A1: List of seeds that can be found in this document with useful spreads (all less than 60,000 advances)
A2: If you find more useful combinations, use the comment function here or send a Discord message to Mucks#1222
A3: Full 32-bit Seed | B3: Seed | C3: Advances | D3: Settings | E3: Held Button | F3: Description | G3: Method
A4: 9C3F9891 | B4: 16a3 | C4: 42814 | D4: MONO/L=A | E4: None | F4: 5 IV Bold | G4: Method 1 | I4: * There is no 6*31 IV spread for this nature so there might be some 30 IVs
A5: 0A721A97 | B5: db2f | C5: 44168 | D5: MONO/L=A | E5: Yes | F5: 5 IV Calm | G5: Method 1
A6: E0A45758 | B6: 19d2 | C6: 57390 | D6: STEREO/L=A | E6: None | F6: 5 IV Calm | G6: Method 1
A7: 86BCEDEA | B7: b1a2 | C7: 21512 | D7: MONO/L=A | E7: None | F7: 5 IV Careful | G7: Method 1
A8: 03558E51 | B8: 1bff | C8: 41490 | D8: MONO/LR | E8: Yes | F8: 5 IV Careful | G8: Method 1
A9: BC1E724E | B9: 91a8 | C9: 35774 | D9: MONO/HELP | E9: None | F9: 5 IV Impish | G9: Method 1 | I9: To check the details of a spread quickly, paste the 32-bit seed into the Generator tab of Pokefinder while choosing the specified method. The first result is the desired spread.
A10: 95B50B03 | B10: 765d | C10: 26150 | D10: MONO/L=A | E10: None | F10: 5 IV Impish | G10: Method 1
A11: 900B2735 | B11: 087c | C11: 58887 | D11: MONO/L=A | E11: None | F11: 5 IV Jolly | G11: Method 1
A12: 9BA21EDF | B12: 710c | C12: 58257 | D12: STEREO/HELP | E12: Yes | F12: 5 IV Modest | G12: Method 1
A13: 1BA21EDF | B13: 84d0 | C13: 51309 | D13: MONO/HELP | E13: None | F13: 5 IV Timid | G13: Method 1
A14: BFF5F86F | B14: 55da | C14: 25627 | D14: STEREO/L=A | E14: Yes | F14: 6 IV* Hasty | G14: Method 1
A15: CCC0FD4E | B15: 88ed | C15: 25963 | D15: MONO/L=A | E15: Yes | F15: 6 IV* Hasty | G15: Method 1
A16: 8BF31F1A | B16: 1377 | C16: 5245 | D16: MONO/LR | E16: Yes | F16: 6 IV* Lonely | G16: Method 1
A17: 9BE82FFE | B17: c887 | C17: 9105 | D17: STEREO/L=A | E17: None | F17: 6 IV* Lonely | G17: Method 1
A18: 959FFCB8 | B18: cc28 | C18: 6544 | D18: STEREO/L=A | E18: None | F18: 6 IV* Mild | G18: Method 1
A19: EDFFFCB8 | B19: 2186 | C19: 28762 | D19: STEREO/LR | E19: Yes | F19: 5 IV Jolly HP Flying (31 Speed) | G19: Method 1
A20: C9907D03 | B20: e0ec | C20: 34629 | D20: MONO/LR | E20: None | F20: 5 IV Jolly HP Flying (31 Speed) | G20: Method 1
A21: 692EB132 | B21: 6be5 | C21: 19831 | D21: MONO/L=A | E21: Yes | F21: 5 IV Adamant HP Flying | G21: Method 1
... A62: DF3259E5 | B62: 1d31 | C62: 24004 | D62: STEREO/LR | E62: None | F62: Special Sassy 31 Speed | G62: Method 1

Sheet Useful Seeds
A1: List of seeds that can be found in this document with useful spreads (limit at 60,000 advances)
A2: If you find more useful combinations, use the comment function here or send a Discord message to Mucks#1222
A3: Full 32-bit Seed | B3: Seed | C3: Advances | D3: Settings | E3: Held Button | F3: Slot | G3: Nature | H3: Ability | I3: HP | J3: Atk | K3: Def | L3: SpA | M3: SpD | N3: Spe | O3: HP Type | P3: Power | Q3: Method
A4: 9C3F9891 | B4: 16a3 | C4: 42814 | D4: MONO/L=A | E4: None | F4: - | G4: Bold | H4: 0 | I4: 31 | J4: 17 | K4: 31 | L4: 31 | M4: 31 | N4: 31 | O4: Dark | P4: 68 | Q4: Method 1 | R4: Static
A5: 0A721A97 | B5: db2f | C5: 44168 | D5: MONO/L=A | E5: Yes | F5: - | G5: Calm | H5: 1 | I5: 31 | J5: 2 | K5: 31 | L5: 31 | M5: 31 | N5: 31 | O5: Dragon | P5: 70 | Q5: Method 1 | R5: 5 IV or 6 IV Spreads
A6: E0A45758 | B6: 19d2 | C6: 57390 | D6: STEREO/L=A | E6: None | F6: - | G6: Calm | H6: 0 | I6: 31 | J6: 5 | K6: 31 | L6: 31 | M6: 31 | N6: 31 | O6: Dark | P6: 68 | Q6: Method 1
A7: 86BCEDEA | B7: b1a2 | C7: 21512 | D7: MONO/L=A | E7: None | F7: - | G7: Careful | H7: 0 | I7: 31 | J7: 31 | K7: 31 | L7: 13 | M7: 31 | N7: 31 | O7: Dark | P7: 59 | Q7: Method 1
A8: 03558E51 | B8: 1bff | C8: 41490 | D8: MONO/LR | E8: Yes | F8: - | G8: Careful | H8: 0 | I8: 31 | J8: 31 | K8: 31 | L8: 30 | M8: 31 | N8: 31 | O8: Electric | P8: 70 | Q8: Method 1
A9: BC1E724E | B9: 91a8 | C9: 35774 | D9: MONO/HELP | E9: None | F9: - | G9: Impish | H9: 0 | I9: 31 | J9: 31 | K9: 31 | L9: 1 | M9: 31 | N9: 31 | O9: Dark | P9: 59 | Q9: Method 1
A10: 95B50B03 | B10: 765d | C10: 26150 | D10: MONO/L=A | E10: None | F10: - | G10: Impish | H10: 0 | I10: 31 | J10: 31 | K10: 31 | L10: 25 | M10: 31 | N10: 31 | O10: Dark | P10: 59 | Q10: Method 1
A11: 900B2735 | B11: 087c | C11: 58887 | D11: MONO/L=A | E11: None | F11: - | G11: Jolly | H11: 0 | I11: 31 | J11: 31 | K11: 31 | L11: 0 | M11: 31 | N11: 31 | O11: Electric | P11: 59 | Q11: Method 1
A12: 9BA21EDF | B12: 710c | C12: 58257 | D12: STEREO/HELP | E12: Yes | F12: - | G12: Modest | H12: 1 | I12: 31 | J12: 12 | K12: 31 | L12: 31 | M12: 31 | N12: 31 | O12: Dragon | P12: 68 | Q12: Method 1
A13: 1BA21EDF | B13: 84d0 | C13: 51309 | D13: MONO/HELP | E13: None | F13: - | G13: Timid | H13: 1 | I13: 31 | J13: 12 | K13: 31 | L13: 31 | M13: 31 | N13: 31 | O13: Dragon | P13: 68 | Q13: Method 1
A14: CFEB0953 | B14: 7962 | C14: 52775 | D14: MONO/L=A | E14: None | F14: - | G14: Hasty | H14: 0 | I14: 30 | J14: 31 | K14: 30 | L14: 30 | M14: 30 | N14: 30 | O14: Fighting | P14: 70 | Q14: Method 1
A15: BFF5F86F | B15: 55da | C15: 25627 | D15: STEREO/L=A | E15: Yes | F15: - | G15: Hasty | H15: 0 | I15: 30 | J15: 31 | K15: 30 | L15: 30 | M15: 30 | N15: 31 | O15: Poison | P15: 70 | Q15: Method 1
A16: CCC0FD4E | B16: 88ed | C16: 25963 | D16: MONO/L=A | E16: Yes | F16: - | G16: Hasty | H16: 1 | I16: 31 | J16: 31 | K16: 31 | L16: 31 | M16: 30 | N16: 31 | O16: Steel | P16: 70 | Q16: Method 1
A17: 8BF31F1A | B17: 1377 | C17: 5245 | D17: MONO/LR | E17: Yes | F17: - | G17: Lonely | H17: 0 | I17: 31 | J17: 30 | K17: 31 | L17: 30 | M17: 31 | N17: 31 | O17: Grass | P17: 70 | Q17: Method 1
... A25: 2F68D96A | B25: 33d6 | C25: 16084 | D25: STEREO/LR | E25: None | F25: - | G25: Rash | H25: 1 | I25: 30 | J25: 31 | K25: 31 | L25: 31 | M25: 31 | N25: 30 | O25: Psychic | P25: 70 | Q25: Method 1
A26: 3D64C932 | B26: 6cb1 | C26: 31675 | D26: MONO/L=A | E26: None | F26: - | G26: Jolly | H26: 1 | I26: 30 | J26: 30 | K26: 30 | L26: 2 | M26: 30 | N26: 30 | O26: Fighting | P26: 70 | Q26: Method 1 | R26: Hidden Power Spreads
A27: D9858DE7 | B27: 9b06 | C27: 29191 | D27: STEREO/LR | E27: None | F27: - | G27: Jolly | H27: 0 | I27: 31 | J27: 30 | K27: 30 | L27: 18 | M27: 30 | N27: 30 | O27: Fighting | P27: 70 | Q27: Method 1
A28: CFEB0953 | B28: 7962 | C28: 52775 | D28: MONO/L=A | E28: None | F28: - | G28: Hasty | H28: 0 | I28: 30 | J28: 31 | K28: 30 | L28: 30 | M28: 30 | N28: 30 | O28: Fighting | P28: 70 | Q28: Method 1
A29: 692EB132 | B29: 6be5 | C29: 19831 | D29: MONO/L=A | E29: Yes | F29: - | G29: Adamant | H29: 1 | I29: 31 | J29: 31 | K29: 31 | L29: 22 | M29: 30 | N29: 30 | O29: Flying | P29: 70 | Q29: Method 1
A30: 9D1F8F2D | B30: 9d3d | C30: 53040 | D30: MONO/LR | E30: None | F30: - | G30: Careful | H30: 0 | I30: 31 | J30: 30 | K30: 31 | L30: 14 | M30: 30 | N30: 30 | O30: Flying | P30: 70 | Q30: Method 1
A31: 88B44B00 | B31: 367b | C31: 18903 | D31: MONO/LR | E31: None | F31: - | G31: Impish | H31: 0 | I31: 30 | J31: 31 | K31: 31 | L31: 6 | M31: 30 | N31: 30 | O31: Flying | P31: 70 | Q31: Method 1
A32: EDFFFCB8 | B32: 2186 | C32: 28762 | D32: STEREO/LR | E32: Yes | F32: - | G32: Jolly | H32: 1 | I32: 30 | J32: 30 | K32: 30 | L32: 18 | M32: 30 | N32: 31 | O32: Flying | P32: 70 | Q32: Method 1
A33: C9907D03 | B33: e0ec | C33: 34629 | D33: MONO/LR | E33: None | F33: - | G33: Jolly | H33: 0 | I33: 30 | J33: 30 | K33: 30 | L33: 18 | M33: 30 | N33: 31 | O33: Flying | P33: 70 | Q33: Method 1
A34: 17AC6819 | B34: 931c | C34: 347 | D34: MONO/LR | E34: None | F34: - | G34: Jolly | H34: 0 | I34: 30 | J34: 31 | K34: 31 | L34: 18 | M34: 30 | N34: 30 | O34: Flying | P34: 70 | Q34: Method 1
A35: F7B31BAD | B35: 8d60 | C35: 43867 | D35: MONO/LR | E35: None | F35: - | G35: Jolly | H35: 1 | I35: 31 | J35: 30 | K35: 31 | L35: 26 | M35: 30 | N35: 30 | O35: Flying | P35: 70 | Q35: Method 1
A36: 624AE3B5 | B36: d74f | C36: 35894 | D36: MONO/L=A | E36: Yes | F36: - | G36: Rash | H36: 0 | I36: 30 | J36: 31 | K36: 31 | L36: 30 | M36: 30 | N36: 30 | O36: Flying | P36: 70 | Q36: Method 1
A37: 624AE3B5 | B37: 47e8 | C37: 47291 | D37: MONO/L=A | E37: None | F37: - | G37: Rash | H37: 0 | I37: 30 | J37: 31 | K37: 31 | L37: 30 | M37: 30 | N37: 30 | O37: Flying | P37: 70 | Q37: Method 1
A38: 0C2D8A7E | B38: 5aa6 | C38: 10904 | D38: MONO/HELP | E38: None | F38: - | G38: Adamant | H38: 0 | I38: 30 | J38: 30 | K38: 31 | L38: 26 | M38: 30 | N38: 31 | O38: Poison | P38: 70 | Q38: Method 1
... A90: B9C9960F | B90: b679 | C90: 7478 | D90: STEREO/LR | E90: Yes | F90: - | G90: Modest | H90: 1 | I90: 30 | J90: 11 | K90: 31 | L90: 30 | M90: 31 | N90: 31 | O90: Grass | P90: 70 | Q90: Method 1
A91: C727F0B0 | B91: 6b67 | C91: 15691 | D91: STEREO/LR/Start | E91: Yes | F91: - | G91: Timid | H91: 1 | I91: 31 | J91: 2 | K91: 31 | L91: 30 | M91: 31 | N91: 31 | O91: Grass | P91: 70 | Q91: Method 1
A92: C727F0B0 | B92: 8187 | C92: 58027 | D92: STEREO/L=A | E92: Yes | F92: - | G92: Timid | H92: 1 | I92: 31 | J92: 2 | K92: 31 | L92: 30 | M92: 31 | N92: 31 | O92: Grass | P92: 70 | Q92: Method 1
A93: 8BF31F1A | B93: 1377 | C93: 5245 | D93: MONO/LR | E93: Yes | F93: - | G93: Lonely | H93: 0 | I93: 31 | J93: 30 | K93: 31 | L93: 30 | M93: 31 | N93: 31 | O93: Grass | P93: 70 | Q93: Method 1
A94: 9BE82FFE | B94: c887 | C94: 9105 | D94: STEREO/L=A | E94: None | F94: - | G94: Lonely | H94: 0 | I94: 31 | J94: 30 | K94: 31 | L94: 30 | M94: 31 | N94: 31 | O94: Grass | P94: 70 | Q94: Method 1
A95: 2C85D7DE | B95: cda5 | C95: 5283 | D95: STEREO/LR | E95: Yes | F95: - | G95: Modest | H95: 0 | I95: 31 | J95: 23 | K95: 31 | L95: 30 | M95: 31 | N95: 31 | O95: Electric | P95: 70 | Q95: Method 1
A96: FA66CF1F | B96: e13a | C96: 59691 | D96: STEREO/L=A | E96: None | F96: - | G96: Calm | H96: 0 | I96: 31 | J96: 26 | K96: 31 | L96: 31 | M96: 31 | N96: 30 | O96: Psychic | P96: 70 | Q96: Method 1
A97: 279FCC62 | B97: a69b | C97: 57201 | D97: STEREO/L=A | E97: None | F97: - | G97: Modest | H97: 0 | I97: 30 | J97: 2 | K97: 31 | L97: 31 | M97: 31 | N97: 30 | O97: Psychic | P97: 70 | Q97: Method 1
A98: 93D911D7 | B98: cfca | C98: 10547 | D98: STEREO/L=A | E98: Yes | F98: - | G98: Modest | H98: 0 | I98: 31 | J98: 15 | K98: 30 | L98: 31 | M98: 31 | N98: 30 | O98: Psychic | P98: 70 | Q98: Method 1
...
